Workbook
Name difficulty_level: Production_Center!$AF$21:$AF$23
Name team_members: Production_Center!$AF$8:$AF$16

Sheet Summary
A1: DWR# | B1: ="2026-"&NETWORKDAYS(46030, C1, X2:X13) -> 2026--32878 | C1: =Production_Center!A8 -> 0 | G1: SDL Daily Workload Summary – Bangladesh | X1: NZ Holidays
C2: Item Description | D2: Trgt Rsrcs | E2: Resources | F2: TARGET HRS | G2: Actual HRS | H2: Billable Hrs | I2: LOAD % | X2: 46048 | Y2: Auckland Anniversary Day
C3: Senior members | D3: 2 | E3: =D3 -> 2 | F3: =E3*8 -> 16 | G3: =IF($I$19=0, F3, MIN($H$19, F3)) -> 16 | H3: =IF(AND($G$5<=$F$5,$I$19=0),F3,G3) -> 16 | I3: =IF($H$19<=$F$6,(((D3/D5)*$H$19)/F3),1) -> 0 | T3: Row Labels | U3: ∑ ActualTime | V3: ∑ Value (NZ$) | X3: 46059 | Y3: Waitagi day
C4: Junior members | D4: 3 | E4: =IF(AND(H19<=F5,I19=0),D4,ROUNDUP(G4/8,0)) -> 3 | F4: =3*8 -> 24 | G4: =IF(H19=0,F4,H19 - G3) -> 24 | H4: =IF(AND($G$5<=$F$5,$I$19=0),F4,G4) -> 24 | I4: =IF($H$19<=$F$6,(((D4/D5)*$H$19)/F4),(F4+($H$19-F5))/F4) -> 0 | T4: (blank) | U4: 0 | V4: 0 | X4: 46101 | Y4: Eid-ul-Fitr Holiday
C5: TOTAL | D5: =SUM(D3:D4) -> 5 | E5: =SUM(E3:E4) -> 5 | F5: 40 | G5: =$H$19 -> 0 | H5: =SUM(H3:H4) -> 40 | I5: =$H$19/$F$5 -> 0 | T5: 0 | U5: 0 | V5: 0 | X5: 46114 | Y5: Good Friday
C6: SDL Estimation | D6: 5 | E6: 5 | F6: 40 | G6: =$G$19 -> 0 | H6: =IF(G6<F6,F6,G6) -> 40 | I6: =$G$19/$F$5 -> 0 | T6: Grand Total | U6: 0 | V6: 0 | X6: 46118 | Y6: Easter Monday
X7: 46139 | Y7: ANZAC Day
A8: PC Job Counts and Time (Hrs) | J8: PC Job Counts and Time (Hrs) | X8: 46170 | Y8: Eid-ul-Adha Holiday
X9: 46171 | Y9: Eid-ul-Adha Holiday
A10: Quotations | J10: Orders | X10: 46174 | Y10: King's Birthday
A11: Target | B11: Done | C11: WIP | D11: Pending | E11: Actual | F11: Overdue | G11: Parts | H11: Parts | I11: Value | J11: Target | K11: Done | L11: WIP | M11: Pending | N11: Actual | O11: Overdue | P11: Parts | Q11: Parts | R11: Value | X11: 46192 | Y11: Matariki Day
A12: Qty | B12: Qty | C12: Qty | D12: Qty | E12: Hrs | F12: Hrs | G12: Done | H12: Left | I12: (NZD) | J12: Qty | K12: Qty | L12: Qty | M12: Qty | N12: Hrs | O12: Hrs | P12: Done | Q12: Left | R12: (NZD) | X12: 46321 | Y12: Labour Day
A13: =Production_Center!$F$113 -> 0 | B13: =Production_Center!$C$113 -> 0 | C13: =Production_Center!$D$113 -> 0 | D13: =Production_Center!$E$113 -> 0 | E13: =Production_Center!$G$113+Production_Center!$H$113 -> 0 | F13: =Production_Center!$I$113 -> 0 | G13: =Production_Center!M113 -> 0 | H13: =Production_Center!N113 -> 0 | I13: =Production_Center!K113 -> 0 | J13: =Production_Center!F112 -> 0 | K13: =Production_Center!C112 -> 0 | L13: =Production_Center!D112 -> 0 | M13: =Production_Center!E112 -> 0 | N13: =Production_Center!$G$112+Production_Center!$H$112 -> 0 | O13: =Production_Center!$I$112 -> 0 | P13: =Production_Center!M112 -> 0 | Q13: =Production_Center!N112 -> 0 | R13: =Production_Center!$K$112 -> 0 | X13: 11 | Y13: days
A15: Total Jobs
A16: Total Jobs (Quotation + Orders)
A17: Target | B17: Jobs | C17: Jobs | D17: Jobs | E17: Parts | F17: Parts | G17: Estmtd | H17: Actual | I17: Pending | J17: Value
A18: Jobs | B18: Done | C18: WIP | D18: Left | E18: Done | F18: Left | G18: Hrs | H18: Hrs | I18: Hrs | J18: (NZD)
A19: =Production_Center!F115 -> #VALUE! | B19: =Production_Center!C115 -> 0 | C19: =Production_Center!D115 -> 0 | D19: =Production_Center!E115 -> 0 | E19: =Production_Center!M115 -> 0 | F19: =Production_Center!N115 -> 0 | G19: =Production_Center!$P$109 -> 0 | H19: =Production_Center!$B$5 -> 0 | I19: =Production_Center!$I$115 -> 0 | J19: =Production_Center!$K$5 -> 0

Sheet Production_Center
B1: Total | D1: Fixed OH hr/job | F1: =10/60 -> 0.16666667 | L1: Production Center – Daily Tasks | N1: Hr/Quot Part | O1: =4.5/60 -> 0.075 | P1: Total | Q1: Remaining | U1: Total | Z1: Status | AA1: Total | AB1: Total | AC1: Job_Type | AD1: Nos.
B2: =AA2/P2 -> #DIV/0! | D2: Part threshold #1 | F2: 31 | N2: Hr/Ordr Part | O2: =6.5/60 -> 0.10833333 | P2: =U109 -> 0 | Q2: =SUMIFS($U$8:$U$108,$Y$8:$Y$108,"<>"&$Z$4) -> 0 | U2: {=SUM(SUMIFS($U$8:$U$108, $Y$8:$Y$108, _xlfn.VSTACK($Z$2, $Z$4)))} -> 0 | X2: Production Center Total SDL time | Y2: =P2 -> 0 | Z2: IP | AA2: =SUM(AA8:AA108) -> 0 | AB2: =SUM(AB8:AB108) -> 0 | AC2: D | AD2: =COUNTIF($D$8:$D$108,AC2) -> 0
D3: Part threshold #2 | F3: 31 | N3: Hr/Drw Part | O3: =4.5/60 -> 0.075 | X3: Total Completed BD time for PC | Y3: =T2 -> 0 | Z3: NA | AC3: O | AD3: =COUNTIF($D$8:$D$108,AC3) -> 0
A4: Jobs | B4: WokDone | C4: Q Left | D4: Q LeftHrs | E4: O Left | F4: O LeftHrs | H4: PartsDone | I4: PartsActed | K4: Value (NZ$) | N4: Cmplt Q Nos, HRs, $ | O4: =COUNTIFS($D$8:$D$108, $AC$4, $Y$8:$Y$108, $Z$4) -> 0 | P4: =SUMIFS($U$8:$U$108, $Y$8:$Y$108, $Z$4, $D$8:$D$108, $AC$4) -> 0 | Q4: =SUMIFS($J$8:$J$108, $Y$8:$Y$108, $Z$4, $D$8:$D$108, $AC$4) -> 0 | R4: =SUMIFS($K$8:$K$108, $Y$8:$Y$108, $Z$4, $D$8:$D$108, $AC$4) -> 0 | S4: Left Q Value $ | T4: =SUMIFS($K$8:$K$108, $Y$8:$Y$108, "<>"&$Z$4, $D$8:$D$108, $AC$4) -> 0 | U4: =SUMIFS($F$8:$F$108, $Y$8:$Y$108, "<>"&$Z$4, $D$8:$D$108, $AC$4) -> 0 | Z4: C | AC4: Q | AD4: =COUNTIF($D$8:$D$108,AC4) -> 0
A5: =MAX($C$8:$C$108) -> 1 | B5: =U2 -> 0 | C5: =$D$113 -> 0 | D5: {=SUM(SUMIFS($U$8:$U$108, $Y$8:$Y$108, _xlfn.VSTACK($Z$2, $Z$4), $D$8:$D$108, $AC$4))} -> 0 | E5: =$D$112 -> 0 | F5: {=SUM(SUMIFS($U$8:$U$108, $Y$8:$Y$108, _xlfn.VSTACK($Z$2, $Z$4), $D$8:$D$108, $AC$2))} -> 0 | I5: {=SUM(SUMIF($Y$8:$Y$108, _xlfn.VSTACK($Z$2, $Z$4), $H$8:$H$108))} -> 0 | K5: {=SUM(SUMIF($Y$8:$Y$108, _xlfn.VSTACK($Z$2, $Z$4), $K$8:$K$108))} -> 0 | N5: Cmplt O Nos, HRs, $ | O5: =COUNTIFS($D$8:$D$108, $AC$3, $Y$8:$Y$108, $Z$4) -> 0 | P5: =SUMIFS($U$8:$U$108, $Y$8:$Y$108, $Z$4, $D$8:$D$108, $AC$3) -> 0 | Q5: =SUMIFS($J$8:$J$108, $Y$8:$Y$108, $Z$4, $D$8:$D$108, $AC$3) -> 0 | R5: =SUMIFS($K$8:$K$108, $Y$8:$Y$108, $Z$4, $D$8:$D$108, $AC$3) -> 0 | S5: Left O Value $ | T5: =SUMIFS($K$8:$K$108, $Y$8:$Y$108, "<>"&$Z$4, $D$8:$D$108, $AC$3) -> 0 | U5: =SUMIFS($F$8:$F$108, $Y$8:$Y$108, "<>"&$Z$4, $D$8:$D$108, $AC$3) -> 0 | Z5: GU | AC5: T | AD5: =COUNTIF($D$8:$D$108,AC5) -> 0
AC6: Total: | AD6: =COUNTIF($D$8:$D$108,AC6) -> 0
A7: Date | B7: Done | C7: Job No | D7: Type | E7: Quote/ Order No. | F7: Parts | G7: Parts Cmltd | H7: Parts Done | I7: Parts Acted | J7: Solo Parts | K7: Value (NZ$) | L7: Customer | M7: Done By | N7: QC By | O7: Grp Work | P7: SDL time | Q7: Sggstd time | R7: Making Time | S7: QC Time | T7: Work time | U7: RM Time | V7: Priority | W7: Difficulty | X7: Details | Y7: Status | AA7: CH | AB7: CEH | AF7: Team Members
B8: {=_xlfn.IFS(Y8=$Z$2,IF(U8="","",IF(G8/F8=0,U8/Q8,G8/F8)),Y8=$Z$3,0,Y8=$Z$4,1)} -> 1 | C8: 1 | F8: =IF(E8=E7,F7,0) -> 0 | G8: =IF(O8="Continued","",F8) -> 0 | H8: =IF(O8="Continued","",F8) -> 0 | I8: {=_xlfn.IFS(Y8=$Z$4,F8,Y8=$Z$3,0,Y8=#REF!,0,Y8=$Z$2,F8-1)} -> 0 | J8: {=_xlfn.IFS(Y8=$Z$4,F8,Y8=$Z$3,0,Y8=#REF!,0,Y8=$Z$2,F8-1)} -> 0 | K8: 0 | Q8: =(IF(D8="Q",F8*$O$1,IF(D8="O",F8*$O$2,F8*$O$3))*IF(F8<$F$2,1,IF(F8<$F$3,0.9,0.875)))+$F$1 -> 0.16666667 | R8: 0 | T8: =R8+S8 -> 0 | U8: =IF(O8="Continued","",SUMIFS($T$6:$T$106,$E$6:$E$106,E8,$D$6:$D$106,D8)) -> 0 | V8: 2 | W8: Basic | Y8: C | Z8: =IF(Q8="","",(Q8-T8)/Q8) -> 1 | AA8: =IF(Y8=$Z$2,IF(B8="","",AB8*B8),AB8) -> 0 | AB8: =IF(Y8="LO",P8*B8,P8) -> 0 | AF8: AIK
A9: =A8 -> 0 | B9: {=_xlfn.IFS(Y9=$Z$2,IF(U9="","",IF(G9/F9=0,U9/Q9,G9/F9)),Y9=$Z$3,0,Y9=$Z$4,1)} -> 1 | C9: =IF(AND(D8=D9,OR(E9=E8,Y9=$Z$3)),C8,IF(E9="","",C8+1)) -> 1 | F9: =IF(E9=E8,F8,0) -> 0 | G9: =IF(O9="Continued","",F9) -> 0 | H9: =IF(O9="Continued","",F9) -> 0 | I9: {=_xlfn.IFS(Y9=$Z$4,F9,Y9=$Z$3,0,Y9=#REF!,0,Y9=$Z$2,F9-1)} -> 0 | J9: {=_xlfn.IFS(Y9=$Z$4,F9,Y9=$Z$3,0,Y9=#REF!,0,Y9=$Z$2,F9-1)} -> 0 | K9: 0 | Q9: =(IF(D9="Q",F9*$O$1,IF(D9="O",F9*$O$2,F9*$O$3))*IF(F9<$F$2,1,IF(F9<$F$3,0.9,0.875)))+$F$1 -> 0.16666667 | R9: 0 | T9: =R9+S9 -> 0 | U9: =IF(O9="Continued","",SUMIFS($T$6:$T$106,$E$6:$E$106,E9,$D$6:$D$106,D9)) -> 0 | V9: 2 | W9: Basic | Y9: C | Z9: =IF(Q9="","",(Q9-T9)/Q9) -> 1 | AA9: =IF(Y9=$Z$2,IF(B9="","",AB9*B9),AB9) -> 0 | AB9: =IF(Y9="LO",P9*B9,P9) -> 0 | AF9: AQZ
A10: =A9 -> 0 | B10: {=_xlfn.IFS(Y10=$Z$2,IF(U10="","",IF(G10/F10=0,U10/Q10,G10/F10)),Y10=$Z$3,0,Y10=$Z$4,1)} -> 1 | C10: =IF(AND(D9=D10,OR(E10=E9,Y10=$Z$3)),C9,IF(E10="","",C9+1)) -> 1 | F10: =IF(E10=E9,F9,0) -> 0 | G10: =IF(O10="Continued","",F10) -> 0 | H10: =IF(O10="Continued","",F10) -> 0 | I10: {=_xlfn.IFS(Y10=$Z$4,F10,Y10=$Z$3,0,Y10=#REF!,0,Y10=$Z$2,F10-1)} -> 0 | J10: {=_xlfn.IFS(Y10=$Z$4,F10,Y10=$Z$3,0,Y10=#REF!,0,Y10=$Z$2,F10-1)} -> 0 | K10: 0 | Q10: =(IF(D10="Q",F10*$O$1,IF(D10="O",F10*$O$2,F10*$O$3))*IF(F10<$F$2,1,IF(F10<$F$3,0.9,0.875)))+$F$1 -> 0.16666667 | R10: 0 | T10: =R10+S10 -> 0 | U10: =IF(O10="Continued","",SUMIFS($T$6:$T$106,$E$6:$E$106,E10,$D$6:$D$106,D10)) -> 0 | V10: 2 | W10: Basic | Y10: C | Z10: =IF(Q10="","",(Q10-T10)/Q10) -> 1 | AA10: =IF(Y10=$Z$2,IF(B10="","",AB10*B10),AB10) -> 0 | AB10: =IF(Y10="LO",P10*B10,P10) -> 0 | AF10: BJM
A11: =A10 -> 0 | B11: {=_xlfn.IFS(Y11=$Z$2,IF(U11="","",IF(G11/F11=0,U11/Q11,G11/F11)),Y11=$Z$3,0,Y11=$Z$4,1)} -> 1 | C11: =IF(AND(D10=D11,OR(E11=E10,Y11=$Z$3)),C10,IF(E11="","",C10+1)) -> 1 | F11: =IF(E11=E10,F10,0) -> 0 | G11: =IF(O11="Continued","",F11) -> 0 | H11: =IF(O11="Continued","",F11) -> 0 | I11: {=_xlfn.IFS(Y11=$Z$4,F11,Y11=$Z$3,0,Y11=#REF!,0,Y11=$Z$2,F11-1)} -> 0 | J11: {=_xlfn.IFS(Y11=$Z$4,F11,Y11=$Z$3,0,Y11=#REF!,0,Y11=$Z$2,F11-1)} -> 0 | K11: 0 | Q11: =(IF(D11="Q",F11*$O$1,IF(D11="O",F11*$O$2,F11*$O$3))*IF(F11<$F$2,1,IF(F11<$F$3,0.9,0.875)))+$F$1 -> 0.16666667 | R11: 0 | T11: =R11+S11 -> 0 | U11: =IF(O11="Continued","",SUMIFS($T$6:$T$106,$E$6:$E$106,E11,$D$6:$D$106,D11)) -> 0 | V11: 2 | W11: Basic | Y11: C | Z11: =IF(Q11="","",(Q11-T11)/Q11) -> 1 | AA11: =IF(Y11=$Z$2,IF(B11="","",AB11*B11),AB11) -> 0 | AB11: =IF(Y11="LO",P11*B11,P11) -> 0 | AF11: SRF
A12: =A11 -> 0 | B12: {=_xlfn.IFS(Y12=$Z$2,IF(U12="","",IF(G12/F12=0,U12/Q12,G12/F12)),Y12=$Z$3,0,Y12=$Z$4,1)} -> 1 | C12: =IF(AND(D11=D12,OR(E12=E11,Y12=$Z$3)),C11,IF(E12="","",C11+1)) -> 1 | F12: =IF(E12=E11,F11,0) -> 0 | G12: =IF(O12="Continued","",F12) -> 0 | H12: =IF(O12="Continued","",F12) -> 0 | I12: {=_xlfn.IFS(Y12=$Z$4,F12,Y12=$Z$3,0,Y12=#REF!,0,Y12=$Z$2,F12-1)} -> 0 | J12: {=_xlfn.IFS(Y12=$Z$4,F12,Y12=$Z$3,0,Y12=#REF!,0,Y12=$Z$2,F12-1)} -> 0 | K12: 0 | Q12: =(IF(D12="Q",F12*$O$1,IF(D12="O",F12*$O$2,F12*$O$3))*IF(F12<$F$2,1,IF(F12<$F$3,0.9,0.875)))+$F$1 -> 0.16666667 | R12: 0 | T12: =R12+S12 -> 0 | U12: =IF(O12="Continued","",SUMIFS($T$6:$T$106,$E$6:$E$106,E12,$D$6:$D$106,D12)) -> 0 | V12: 2 | W12: Basic | Y12: C | Z12: =IF(Q12="","",(Q12-T12)/Q12) -> 1 | AA12: =IF(Y12=$Z$2,IF(B12="","",AB12*B12),AB12) -> 0 | AB12: =IF(Y12="LO",P12*B12,P12) -> 0 | AF12: MB
A13: =A12 -> 0 | B13: {=_xlfn.IFS(Y13=$Z$2,IF(U13="","",IF(G13/F13=0,U13/Q13,G13/F13)),Y13=$Z$3,0,Y13=$Z$4,1)} -> 1 | C13: =IF(AND(D12=D13,OR(E13=E12,Y13=$Z$3)),C12,IF(E13="","",C12+1)) -> 1 | F13: =IF(E13=E12,F12,0) -> 0 | G13: =IF(O13="Continued","",F13) -> 0 | H13: =IF(O13="Continued","",F13) -> 0 | I13: {=_xlfn.IFS(Y13=$Z$4,F13,Y13=$Z$3,0,Y13=#REF!,0,Y13=$Z$2,F13-1)} -> 0 | J13: {=_xlfn.IFS(Y13=$Z$4,F13,Y13=$Z$3,0,Y13=#REF!,0,Y13=$Z$2,F13-1)} -> 0 | K13: 0 | Q13: =(IF(D13="Q",F13*$O$1,IF(D13="O",F13*$O$2,F13*$O$3))*IF(F13<$F$2,1,IF(F13<$F$3,0.9,0.875)))+$F$1 -> 0.16666667 | R13: 0 | T13: =R13+S13 -> 0 | U13: =IF(O13="Continued","",SUMIFS($T$6:$T$106,$E$6:$E$106,E13,$D$6:$D$106,D13)) -> 0 | V13: 2 | W13: Basic | Y13: C | Z13: =IF(Q13="","",(Q13-T13)/Q13) -> 1 | AA13: =IF(Y13=$Z$2,IF(B13="","",AB13*B13),AB13) -> 0 | AB13: =IF(Y13="LO",P13*B13,P13) -> 0 | AF13: ZH
A14: =A13 -> 0 | B14: {=_xlfn.IFS(Y14=$Z$2,IF(U14="","",IF(G14/F14=0,U14/Q14,G14/F14)),Y14=$Z$3,0,Y14=$Z$4,1)} -> 1 | C14: =IF(AND(D13=D14,OR(E14=E13,Y14=$Z$3)),C13,IF(E14="","",C13+1)) -> 1 | F14: =IF(E14=E13,F13,0) -> 0 | G14: =IF(O14="Continued","",F14) -> 0 | H14: =IF(O14="Continued","",F14) -> 0 | I14: {=_xlfn.IFS(Y14=$Z$4,F14,Y14=$Z$3,0,Y14=#REF!,0,Y14=$Z$2,F14-1)} -> 0 | J14: {=_xlfn.IFS(Y14=$Z$4,F14,Y14=$Z$3,0,Y14=#REF!,0,Y14=$Z$2,F14-1)} -> 0 | K14: 0 | Q14: =(IF(D14="Q",F14*$O$1,IF(D14="O",F14*$O$2,F14*$O$3))*IF(F14<$F$2,1,IF(F14<$F$3,0.9,0.875)))+$F$1 -> 0.16666667 | R14: 0 | T14: =R14+S14 -> 0 | U14: =IF(O14="Continued","",SUMIFS($T$6:$T$106,$E$6:$E$106,E14,$D$6:$D$106,D14)) -> 0 | V14: 2 | W14: Basic | Y14: C | Z14: =IF(Q14="","",(Q14-T14)/Q14) -> 1 | AA14: =IF(Y14=$Z$2,IF(B14="","",AB14*B14),AB14) -> 0 | AB14: =IF(Y14="LO",P14*B14,P14) -> 0 | AF14: NM
A15: =A14 -> 0 | B15: {=_xlfn.IFS(Y15=$Z$2,IF(U15="","",IF(G15/F15=0,U15/Q15,G15/F15)),Y15=$Z$3,0,Y15=$Z$4,1)} -> 1 | C15: =IF(AND(D14=D15,OR(E15=E14,Y15=$Z$3)),C14,IF(E15="","",C14+1)) -> 1 | F15: =IF(E15=E14,F14,0) -> 0 | G15: =IF(O15="Continued","",F15) -> 0 | H15: =IF(O15="Continued","",F15) -> 0 | I15: {=_xlfn.IFS(Y15=$Z$4,F15,Y15=$Z$3,0,Y15=#REF!,0,Y15=$Z$2,F15-1)} -> 0 | J15: {=_xlfn.IFS(Y15=$Z$4,F15,Y15=$Z$3,0,Y15=#REF!,0,Y15=$Z$2,F15-1)} -> 0 | K15: 0 | Q15: =(IF(D15="Q",F15*$O$1,IF(D15="O",F15*$O$2,F15*$O$3))*IF(F15<$F$2,1,IF(F15<$F$3,0.9,0.875)))+$F$1 -> 0.16666667 | R15: 0 | T15: =R15+S15 -> 0 | U15: =IF(O15="Continued","",SUMIFS($T$6:$T$106,$E$6:$E$106,E15,$D$6:$D$106,D15)) -> 0 | V15: 2 | W15: Basic | Y15: C | Z15: =IF(Q15="","",(Q15-T15)/Q15) -> 1 | AA15: =IF(Y15=$Z$2,IF(B15="","",AB15*B15),AB15) -> 0 | AB15: =IF(Y15="LO",P15*B15,P15) -> 0 | AF15: SH
A16: =A15 -> 0 | B16: {=_xlfn.IFS(Y16=$Z$2,IF(U16="","",IF(G16/F16=0,U16/Q16,G16/F16)),Y16=$Z$3,0,Y16=$Z$4,1)} -> 1 | C16: =IF(AND(D15=D16,OR(E16=E15,Y16=$Z$3)),C15,IF(E16="","",C15+1)) -> 1 | F16: =IF(E16=E15,F15,0) -> 0 | G16: =IF(O16="Continued","",F16) -> 0 | H16: =IF(O16="Continued","",F16) -> 0 | I16: {=_xlfn.IFS(Y16=$Z$4,F16,Y16=$Z$3,0,Y16=#REF!,0,Y16=$Z$2,F16-1)} -> 0 | J16: {=_xlfn.IFS(Y16=$Z$4,F16,Y16=$Z$3,0,Y16=#REF!,0,Y16=$Z$2,F16-1)} -> 0 | K16: 0 | Q16: =IF(O16="Continued","",(IF(D16="Q",F16*$O$1,IF(D16="O",F16*$O$2,F16*$O$3))*IF(F16<$F$2,1,IF(F16<$F$3,0.9,0.875)))+$F$1) -> 0.16666667 | R16: 0 | T16: =R16+S16 -> 0 | U16: =IF(O16="Continued","",SUMIFS($T$6:$T$106,$E$6:$E$106,E16,$D$6:$D$106,D16)) -> 0 | V16: 2 | W16: Basic | Y16: C | Z16: =IF(Q16="","",(Q16-T16)/Q16) -> 1 | AA16: =IF(Y16=$Z$2,IF(B16="","",AB16*B16),AB16) -> 0 | AB16: =IF(Y16="LO",P16*B16,P16) -> 0 | AF16: SI
A17: =A16 -> 0 | B17: {=_xlfn.IFS(Y17=$Z$2,IF(U17="","",IF(G17/F17=0,U17/Q17,G17/F17)),Y17=$Z$3,0,Y17=$Z$4,1)} -> 1 | C17: =IF(AND(D16=D17,OR(E17=E16,Y17=$Z$3)),C16,IF(E17="","",C16+1)) -> 1 | F17: =IF(E17=E16,F16,0) -> 0 | G17: =IF(O17="Continued","",F17) -> 0 | H17: =IF(O17="Continued","",F17) -> 0 | I17: {=_xlfn.IFS(Y17=$Z$4,F17,Y17=$Z$3,0,Y17=#REF!,0,Y17=$Z$2,F17-1)} -> 0 | J17: {=_xlfn.IFS(Y17=$Z$4,F17,Y17=$Z$3,0,Y17=#REF!,0,Y17=$Z$2,F17-1)} -> 0 | K17: 0 | Q17: =IF(O17="Continued","",(IF(D17="Q",F17*$O$1,IF(D17="O",F17*$O$2,F17*$O$3))*IF(F17<$F$2,1,IF(F17<$F$3,0.9,0.875)))+$F$1) -> 0.16666667 | R17: 0 | T17: =R17+S17 -> 0 | U17: =IF(O17="Continued","",SUMIFS($T$6:$T$106,$E$6:$E$106,E17,$D$6:$D$106,D17)) -> 0 | V17: 2 | W17: Basic | Y17: C | Z17: =IF(Q17="","",(Q17-T17)/Q17) -> 1 | AA17: =IF(Y17=$Z$2,IF(B17="","",AB17*B17),AB17) -> 0 | AB17: =IF(Y17="LO",P17*B17,P17) -> 0
A18: =A17 -> 0 | B18: {=_xlfn.IFS(Y18=$Z$2,IF(U18="","",IF(G18/F18=0,U18/Q18,G18/F18)),Y18=$Z$3,0,Y18=$Z$4,1)} -> 1 | C18: =IF(AND(D17=D18,OR(E18=E17,Y18=$Z$3)),C17,IF(E18="","",C17+1)) -> 1 | F18: =IF(E18=E17,F17,0) -> 0 | G18: =IF(O18="Continued","",F18) -> 0 | H18: =IF(O18="Continued","",F18) -> 0 | I18: {=_xlfn.IFS(Y18=$Z$4,F18,Y18=$Z$3,0,Y18=#REF!,0,Y18=$Z$2,F18-1)} -> 0 | J18: {=_xlfn.IFS(Y18=$Z$4,F18,Y18=$Z$3,0,Y18=#REF!,0,Y18=$Z$2,F18-1)} -> 0 | K18: 0 | Q18: =IF(O18="Continued","",(IF(D18="Q",F18*$O$1,IF(D18="O",F18*$O$2,F18*$O$3))*IF(F18<$F$2,1,IF(F18<$F$3,0.9,0.875)))+$F$1) -> 0.16666667 | R18: 0 | T18: =R18+S18 -> 0 | U18: =IF(O18="Continued","",SUMIFS($T$6:$T$106,$E$6:$E$106,E18,$D$6:$D$106,D18)) -> 0 | V18: 2 | W18: Basic | Y18: C | Z18: =IF(Q18="","",(Q18-T18)/Q18) -> 1 | AA18: =IF(Y18=$Z$2,IF(B18="","",AB18*B18),AB18) -> 0 | AB18: =IF(Y18="LO",P18*B18,P18) -> 0
A19: =A18 -> 0 | B19: {=_xlfn.IFS(Y19=$Z$2,IF(U19="","",IF(G19/F19=0,U19/Q19,G19/F19)),Y19=$Z$3,0,Y19=$Z$4,1)} -> 1 | C19: =IF(AND(D18=D19,OR(E19=E18,Y19=$Z$3)),C18,IF(E19="","",C18+1)) -> 1 | F19: =IF(E19=E18,F18,0) -> 0 | G19: =IF(O19="Continued","",F19) -> 0 | H19: =IF(O19="Continued","",F19) -> 0 | I19: {=_xlfn.IFS(Y19=$Z$4,F19,Y19=$Z$3,0,Y19=#REF!,0,Y19=$Z$2,F19-1)} -> 0 | J19: {=_xlfn.IFS(Y19=$Z$4,F19,Y19=$Z$3,0,Y19=#REF!,0,Y19=$Z$2,F19-1)} -> 0 | K19: 0 | Q19: =IF(O19="Continued","",(IF(D19="Q",F19*$O$1,IF(D19="O",F19*$O$2,F19*$O$3))*IF(F19<$F$2,1,IF(F19<$F$3,0.9,0.875)))+$F$1) -> 0.16666667 | R19: 0 | T19: =R19+S19 -> 0 | U19: =IF(O19="Continued","",SUMIFS($T$6:$T$106,$E$6:$E$106,E19,$D$6:$D$106,D19)) -> 0 | V19: 2 | W19: Basic | Y19: C | Z19: =IF(Q19="","",(Q19-T19)/Q19) -> 1 | AA19: =IF(Y19=$Z$2,IF(B19="","",AB19*B19),AB19) -> 0 | AB19: =IF(Y19="LO",P19*B19,P19) -> 0
A20: =A19 -> 0 | B20: {=_xlfn.IFS(Y20=$Z$2,IF(U20="","",IF(G20/F20=0,U20/Q20,G20/F20)),Y20=$Z$3,0,Y20=$Z$4,1)} -> 1 | C20: =IF(AND(D19=D20,OR(E20=E19,Y20=$Z$3)),C19,IF(E20="","",C19+1)) -> 1 | F20: =IF(E20=E19,F19,0) -> 0 | G20: =IF(O20="Continued","",F20) -> 0 | H20: =IF(O20="Continued","",F20) -> 0 | I20: {=_xlfn.IFS(Y20=$Z$4,F20,Y20=$Z$3,0,Y20=#REF!,0,Y20=$Z$2,F20-1)} -> 0 | J20: {=_xlfn.IFS(Y20=$Z$4,F20,Y20=$Z$3,0,Y20=#REF!,0,Y20=$Z$2,F20-1)} -> 0 | K20: 0 | Q20: =IF(O20="Continued","",(IF(D20="Q",F20*$O$1,IF(D20="O",F20*$O$2,F20*$O$3))*IF(F20<$F$2,1,IF(F20<$F$3,0.9,0.875)))+$F$1) -> 0.16666667 | R20: 0 | T20: =R20+S20 -> 0 | U20: =IF(O20="Continued","",SUMIFS($T$6:$T$106,$E$6:$E$106,E20,$D$6:$D$106,D20)) -> 0 | V20: 2 | W20: Basic | Y20: C | Z20: =IF(Q20="","",(Q20-T20)/Q20) -> 1 | AA20: =IF(Y20=$Z$2,IF(B20="","",AB20*B20),AB20) -> 0 | AB20: =IF(Y20="LO",P20*B20,P20) -> 0 | AF20: Difficulty
A21: =A20 -> 0 | B21: {=_xlfn.IFS(Y21=$Z$2,IF(U21="","",IF(G21/F21=0,U21/Q21,G21/F21)),Y21=$Z$3,0,Y21=$Z$4,1)} -> 1 | C21: =IF(AND(D20=D21,OR(E21=E20,Y21=$Z$3)),C20,IF(E21="","",C20+1)) -> 1 | F21: =IF(E21=E20,F20,0) -> 0 | G21: =IF(O21="Continued","",F21) -> 0 | H21: =IF(O21="Continued","",F21) -> 0 | I21: {=_xlfn.IFS(Y21=$Z$4,F21,Y21=$Z$3,0,Y21=#REF!,0,Y21=$Z$2,F21-1)} -> 0 | J21: {=_xlfn.IFS(Y21=$Z$4,F21,Y21=$Z$3,0,Y21=#REF!,0,Y21=$Z$2,F21-1)} -> 0 | K21: 0 | Q21: =(IF(D21="Q",F21*$O$1,IF(D21="O",F21*$O$2,F21*$O$3))*IF(F21<$F$2,1,IF(F21<$F$3,0.9,0.875)))+$F$1 -> 0.16666667 | R21: 0 | T21: =R21+S21 -> 0 | U21: =IF(O21="Continued","",SUMIFS($T$6:$T$106,$E$6:$E$106,E21,$D$6:$D$106,D21)) -> 0 | V21: 2 | W21: Basic | Y21: C | Z21: =IF(Q21="","",(Q21-T21)/Q21) -> 1 | AA21: =IF(Y21=$Z$2,IF(B21="","",AB21*B21),AB21) -> 0 | AB21: =IF(Y21="LO",P21*B21,P21) -> 0 | AF21: Basic
A22: =A21 -> 0 | B22: {=_xlfn.IFS(Y22=$Z$2,IF(U22="","",IF(G22/F22=0,U22/Q22,G22/F22)),Y22=$Z$3,0,Y22=$Z$4,1)} -> 1 | C22: =IF(AND(D21=D22,OR(E22=E21,Y22=$Z$3)),C21,IF(E22="","",C21+1)) -> 1 | F22: =IF(E22=E21,F21,0) -> 0 | G22: =IF(O22="Continued","",F22) -> 0 | H22: =IF(O22="Continued","",F22) -> 0 | I22: {=_xlfn.IFS(Y22=$Z$4,F22,Y22=$Z$3,0,Y22=#REF!,0,Y22=$Z$2,F22-1)} -> 0 | J22: {=_xlfn.IFS(Y22=$Z$4,F22,Y22=$Z$3,0,Y22=#REF!,0,Y22=$Z$2,F22-1)} -> 0 | K22: 0 | Q22: =(IF(D22="Q",F22*$O$1,IF(D22="O",F22*$O$2,F22*$O$3))*IF(F22<$F$2,1,IF(F22<$F$3,0.9,0.875)))+$F$1 -> 0.16666667 | R22: 0 | T22: =R22+S22 -> 0 | U22: =IF(O22="Continued","",SUMIFS($T$6:$T$106,$E$6:$E$106,E22,$D$6:$D$106,D22)) -> 0 | V22: 2 | W22: Basic | Y22: C | Z22: =IF(Q22="","",(Q22-T22)/Q22) -> 1 | AA22: =IF(Y22=$Z$2,IF(B22="","",AB22*B22),AB22) -> 0 | AB22: =IF(Y22="LO",P22*B22,P22) -> 0 | AF22: Moderate
A23: =A22 -> 0 | B23: {=_xlfn.IFS(Y23=$Z$2,IF(U23="","",IF(G23/F23=0,U23/Q23,G23/F23)),Y23=$Z$3,0,Y23=$Z$4,1)} -> 1 | C23: =IF(AND(D22=D23,OR(E23=E22,Y23=$Z$3)),C22,IF(E23="","",C22+1)) -> 1 | F23: =IF(E23=E22,F22,0) -> 0 | G23: =IF(O23="Continued","",F23) -> 0 | H23: =IF(O23="Continued","",F23) -> 0 | I23: {=_xlfn.IFS(Y23=$Z$4,F23,Y23=$Z$3,0,Y23=#REF!,0,Y23=$Z$2,F23-1)} -> 0 | J23: {=_xlfn.IFS(Y23=$Z$4,F23,Y23=$Z$3,0,Y23=#REF!,0,Y23=$Z$2,F23-1)} -> 0 | K23: 0 | Q23: =(IF(D23="Q",F23*$O$1,IF(D23="O",F23*$O$2,F23*$O$3))*IF(F23<$F$2,1,IF(F23<$F$3,0.9,0.875)))+$F$1 -> 0.16666667 | R23: 0 | T23: =R23+S23 -> 0 | U23: =IF(O23="Continued","",SUMIFS($T$6:$T$106,$E$6:$E$106,E23,$D$6:$D$106,D23)) -> 0 | V23: 2 | W23: Basic | Y23: C | Z23: =IF(Q23="","",(Q23-T23)/Q23) -> 1 | AA23: =IF(Y23=$Z$2,IF(B23="","",AB23*B23),AB23) -> 0 | AB23: =IF(Y23="LO",P23*B23,P23) -> 0 | AF23: Challenging
A24: =A23 -> 0 | B24: {=_xlfn.IFS(Y24=$Z$2,IF(U24="","",IF(G24/F24=0,U24/Q24,G24/F24)),Y24=$Z$3,0,Y24=$Z$4,1)} -> 1 | C24: =IF(AND(D23=D24,OR(E24=E23,Y24=$Z$3)),C23,IF(E24="","",C23+1)) -> 1 | F24: =IF(E24=E23,F23,0) -> 0 | G24: =IF(O24="Continued","",F24) -> 0 | H24: =IF(O24="Continued","",F24) -> 0 | I24: {=_xlfn.IFS(Y24=$Z$4,F24,Y24=$Z$3,0,Y24=#REF!,0,Y24=$Z$2,F24-1)} -> 0 | J24: {=_xlfn.IFS(Y24=$Z$4,F24,Y24=$Z$3,0,Y24=#REF!,0,Y24=$Z$2,F24-1)} -> 0 | K24: 0 | Q24: =(IF(D24="Q",F24*$O$1,IF(D24="O",F24*$O$2,F24*$O$3))*IF(F24<$F$2,1,IF(F24<$F$3,0.9,0.875)))+$F$1 -> 0.16666667 | R24: 0 | T24: =R24+S24 -> 0 | U24: =IF(O24="Continued","",SUMIFS($T$6:$T$106,$E$6:$E$106,E24,$D$6:$D$106,D24)) -> 0 | V24: 2 | W24: Basic | Y24: C | Z24: =IF(Q24="","",(Q24-T24)/Q24) -> 1 | AA24: =IF(Y24=$Z$2,IF(B24="","",AB24*B24),AB24) -> 0 | AB24: =IF(Y24="LO",P24*B24,P24) -> 0
A25: =A24 -> 0 | B25: {=_xlfn.IFS(Y25=$Z$2,IF(U25="","",IF(G25/F25=0,U25/Q25,G25/F25)),Y25=$Z$3,0,Y25=$Z$4,1)} -> 1 | C25: =IF(AND(D24=D25,OR(E25=E24,Y25=$Z$3)),C24,IF(E25="","",C24+1)) -> 1 | F25: =IF(E25=E24,F24,0) -> 0 | G25: =IF(O25="Continued","",F25) -> 0 | H25: =IF(O25="Continued","",F25) -> 0 | I25: {=_xlfn.IFS(Y25=$Z$4,F25,Y25=$Z$3,0,Y25=#REF!,0,Y25=$Z$2,F25-1)} -> 0 | J25: {=_xlfn.IFS(Y25=$Z$4,F25,Y25=$Z$3,0,Y25=#REF!,0,Y25=$Z$2,F25-1)} -> 0 | K25: 0 | Q25: =(IF(D25="Q",F25*$O$1,IF(D25="O",F25*$O$2,F25*$O$3))*IF(F25<$F$2,1,IF(F25<$F$3,0.9,0.875)))+$F$1 -> 0.16666667 | R25: 0 | T25: =R25+S25 -> 0 | U25: =IF(O25="Continued","",SUMIFS($T$6:$T$106,$E$6:$E$106,E25,$D$6:$D$106,D25)) -> 0 | V25: 2 | W25: Basic | Y25: C | Z25: =IF(Q25="","",(Q25-T25)/Q25) -> 1 | AA25: =IF(Y25=$Z$2,IF(B25="","",AB25*B25),AB25) -> 0 | AB25: =IF(Y25="LO",P25*B25,P25) -> 0
A26: =A25 -> 0 | B26: {=_xlfn.IFS(Y26=$Z$2,IF(U26="","",IF(G26/F26=0,U26/Q26,G26/F26)),Y26=$Z$3,0,Y26=$Z$4,1)} -> 1 | C26: =IF(AND(D25=D26,OR(E26=E25,Y26=$Z$3)),C25,IF(E26="","",C25+1)) -> 1 | F26: =IF(E26=E25,F25,0) -> 0 | G26: =IF(O26="Continued","",F26) -> 0 | H26: =IF(O26="Continued","",F26) -> 0 | I26: {=_xlfn.IFS(Y26=$Z$4,F26,Y26=$Z$3,0,Y26=#REF!,0,Y26=$Z$2,F26-1)} -> 0 | J26: {=_xlfn.IFS(Y26=$Z$4,F26,Y26=$Z$3,0,Y26=#REF!,0,Y26=$Z$2,F26-1)} -> 0 | K26: 0 | Q26: =(IF(D26="Q",F26*$O$1,IF(D26="O",F26*$O$2,F26*$O$3))*IF(F26<$F$2,1,IF(F26<$F$3,0.9,0.875)))+$F$1 -> 0.16666667 | R26: 0 | T26: =R26+S26 -> 0 | U26: =IF(O26="Continued","",SUMIFS($T$6:$T$106,$E$6:$E$106,E26,$D$6:$D$106,D26)) -> 0 | V26: 2 | W26: Basic | Y26: C | Z26: =IF(Q26="","",(Q26-T26)/Q26) -> 1 | AA26: =IF(Y26=$Z$2,IF(B26="","",AB26*B26),AB26) -> 0 | AB26: =IF(Y26="LO",P26*B26,P26) -> 0
A27: =A26 -> 0 | B27: {=_xlfn.IFS(Y27=$Z$2,IF(U27="","",IF(G27/F27=0,U27/Q27,G27/F27)),Y27=$Z$3,0,Y27=$Z$4,1)} -> 1 | C27: =IF(AND(D26=D27,OR(E27=E26,Y27=$Z$3)),C26,IF(E27="","",C26+1)) -> 1 | F27: =IF(E27=E26,F26,0) -> 0 | G27: =IF(O27="Continued","",F27) -> 0 | H27: =IF(O27="Continued","",F27) -> 0 | I27: {=_xlfn.IFS(Y27=$Z$4,F27,Y27=$Z$3,0,Y27=#REF!,0,Y27=$Z$2,F27-1)} -> 0 | J27: {=_xlfn.IFS(Y27=$Z$4,F27,Y27=$Z$3,0,Y27=#REF!,0,Y27=$Z$2,F27-1)} -> 0 | K27: 0 | Q27: =(IF(D27="Q",F27*$O$1,IF(D27="O",F27*$O$2,F27*$O$3))*IF(F27<$F$2,1,IF(F27<$F$3,0.9,0.875)))+$F$1 -> 0.16666667 | R27: 0 | T27: =R27+S27 -> 0 | U27: =IF(O27="Continued","",SUMIFS($T$6:$T$106,$E$6:$E$106,E27,$D$6:$D$106,D27)) -> 0 | V27: 2 | W27: Basic | Y27: C | Z27: =IF(Q27="","",(Q27-T27)/Q27) -> 1 | AA27: =IF(Y27=$Z$2,IF(B27="","",AB27*B27),AB27) -> 0 | AB27: =IF(Y27="LO",P27*B27,P27) -> 0
A28: =A27 -> 0 | B28: {=_xlfn.IFS(Y28=$Z$2,IF(U28="","",IF(G28/F28=0,U28/Q28,G28/F28)),Y28=$Z$3,0,Y28=$Z$4,1)} -> 1 | C28: =IF(AND(D27=D28,OR(E28=E27,Y28=$Z$3)),C27,IF(E28="","",C27+1)) -> 1 | F28: =IF(E28=E27,F27,0) -> 0 | G28: =IF(O28="Continued","",F28) -> 0 | H28: =IF(O28="Continued","",F28) -> 0 | I28: {=_xlfn.IFS(Y28=$Z$4,F28,Y28=$Z$3,0,Y28=#REF!,0,Y28=$Z$2,F28-1)} -> 0 | J28: {=_xlfn.IFS(Y28=$Z$4,F28,Y28=$Z$3,0,Y28=#REF!,0,Y28=$Z$2,F28-1)} -> 0 | K28: 0 | Q28: =(IF(D28="Q",F28*$O$1,IF(D28="O",F28*$O$2,F28*$O$3))*IF(F28<$F$2,1,IF(F28<$F$3,0.9,0.875)))+$F$1 -> 0.16666667 | R28: 0 | T28: =R28+S28 -> 0 | U28: =IF(O28="Continued","",SUMIFS($T$6:$T$106,$E$6:$E$106,E28,$D$6:$D$106,D28)) -> 0 | V28: 2 | W28: Basic | Y28: C | Z28: =IF(Q28="","",(Q28-T28)/Q28) -> 1 | AA28: =IF(Y28=$Z$2,IF(B28="","",AB28*B28),AB28) -> 0 | AB28: =IF(Y28="LO",P28*B28,P28) -> 0
A29: =A28 -> 0 | B29: {=_xlfn.IFS(Y29=$Z$2,IF(U29="","",IF(G29/F29=0,U29/Q29,G29/F29)),Y29=$Z$3,0,Y29=$Z$4,1)} -> 1 | C29: =IF(AND(D28=D29,OR(E29=E28,Y29=$Z$3)),C28,IF(E29="","",C28+1)) -> 1 | F29: =IF(E29=E28,F28,0) -> 0 | G29: =IF(O29="Continued","",F29) -> 0 | H29: =IF(O29="Continued","",F29) -> 0 | I29: {=_xlfn.IFS(Y29=$Z$4,F29,Y29=$Z$3,0,Y29=#REF!,0,Y29=$Z$2,F29-1)} -> 0 | J29: {=_xlfn.IFS(Y29=$Z$4,F29,Y29=$Z$3,0,Y29=#REF!,0,Y29=$Z$2,F29-1)} -> 0 | K29: 0 | Q29: =(IF(D29="Q",F29*$O$1,IF(D29="O",F29*$O$2,F29*$O$3))*IF(F29<$F$2,1,IF(F29<$F$3,0.9,0.875)))+$F$1 -> 0.16666667 | R29: 0 | T29: =R29+S29 -> 0 | U29: =IF(O29="Continued","",SUMIFS($T$6:$T$106,$E$6:$E$106,E29,$D$6:$D$106,D29)) -> 0 | V29: 2 | W29: Basic | Y29: C | Z29: =IF(Q29="","",(Q29-T29)/Q29) -> 1 | AA29: =IF(Y29=$Z$2,IF(B29="","",AB29*B29),AB29) -> 0 | AB29: =IF(Y29="LO",P29*B29,P29) -> 0
A30: =A29 -> 0 | B30: {=_xlfn.IFS(Y30=$Z$2,IF(U30="","",IF(G30/F30=0,U30/Q30,G30/F30)),Y30=$Z$3,0,Y30=$Z$4,1)} -> 1 | C30: =IF(AND(D29=D30,OR(E30=E29,Y30=$Z$3)),C29,IF(E30="","",C29+1)) -> 1 | F30: =IF(E30=E29,F29,0) -> 0 | G30: =IF(O30="Continued","",F30) -> 0 | H30: =IF(O30="Continued","",F30) -> 0 | I30: {=_xlfn.IFS(Y30=$Z$4,F30,Y30=$Z$3,0,Y30=#REF!,0,Y30=$Z$2,F30-1)} -> 0 | J30: {=_xlfn.IFS(Y30=$Z$4,F30,Y30=$Z$3,0,Y30=#REF!,0,Y30=$Z$2,F30-1)} -> 0 | K30: 0 | Q30: =(IF(D30="Q",F30*$O$1,IF(D30="O",F30*$O$2,F30*$O$3))*IF(F30<$F$2,1,IF(F30<$F$3,0.9,0.875)))+$F$1 -> 0.16666667 | R30: 0 | T30: =R30+S30 -> 0 | U30: =IF(O30="Continued","",SUMIFS($T$6:$T$106,$E$6:$E$106,E30,$D$6:$D$106,D30)) -> 0 | V30: 2 | W30: Basic | Y30: C | Z30: =IF(Q30="","",(Q30-T30)/Q30) -> 1 | AA30: =IF(Y30=$Z$2,IF(B30="","",AB30*B30),AB30) -> 0 | AB30: =IF(Y30="LO",P30*B30,P30) -> 0
A31: =A30 -> 0 | B31: {=_xlfn.IFS(Y31=$Z$2,IF(U31="","",IF(G31/F31=0,U31/Q31,G31/F31)),Y31=$Z$3,0,Y31=$Z$4,1)} -> 1 | C31: =IF(AND(D30=D31,OR(E31=E30,Y31=$Z$3)),C30,IF(E31="","",C30+1)) -> 1 | F31: =IF(E31=E30,F30,0) -> 0 | G31: =IF(O31="Continued","",F31) -> 0 | H31: =IF(O31="Continued","",F31) -> 0 | I31: {=_xlfn.IFS(Y31=$Z$4,F31,Y31=$Z$3,0,Y31=#REF!,0,Y31=$Z$2,F31-1)} -> 0 | J31: {=_xlfn.IFS(Y31=$Z$4,F31,Y31=$Z$3,0,Y31=#REF!,0,Y31=$Z$2,F31-1)} -> 0 | K31: 0 | Q31: =(IF(D31="Q",F31*$O$1,IF(D31="O",F31*$O$2,F31*$O$3))*IF(F31<$F$2,1,IF(F31<$F$3,0.9,0.875)))+$F$1 -> 0.16666667 | R31: 0 | T31: =R31+S31 -> 0 | U31: =IF(O31="Continued","",SUMIFS($T$6:$T$106,$E$6:$E$106,E31,$D$6:$D$106,D31)) -> 0 | V31: 2 | W31: Basic | Y31: C | Z31: =IF(Q31="","",(Q31-T31)/Q31) -> 1 | AA31: =IF(Y31=$Z$2,IF(B31="","",AB31*B31),AB31) -> 0 | AB31: =IF(Y31="LO",P31*B31,P31) -> 0
A32: =A31 -> 0 | B32: {=_xlfn.IFS(Y32=$Z$2,IF(U32="","",IF(G32/F32=0,U32/Q32,G32/F32)),Y32=$Z$3,0,Y32=$Z$4,1)} -> 1 | C32: =IF(AND(D31=D32,OR(E32=E31,Y32=$Z$3)),C31,IF(E32="","",C31+1)) -> 1 | F32: =IF(E32=E31,F31,0) -> 0 | G32: =IF(O32="Continued","",F32) -> 0 | H32: =IF(O32="Continued","",F32) -> 0 | I32: {=_xlfn.IFS(Y32=$Z$4,F32,Y32=$Z$3,0,Y32=#REF!,0,Y32=$Z$2,F32-1)} -> 0 | J32: {=_xlfn.IFS(Y32=$Z$4,F32,Y32=$Z$3,0,Y32=#REF!,0,Y32=$Z$2,F32-1)} -> 0 | K32: 0 | Q32: =(IF(D32="Q",F32*$O$1,IF(D32="O",F32*$O$2,F32*$O$3))*IF(F32<$F$2,1,IF(F32<$F$3,0.9,0.875)))+$F$1 -> 0.16666667 | R32: 0 | T32: =R32+S32 -> 0 | U32: =IF(O32="Continued","",SUMIFS($T$6:$T$106,$E$6:$E$106,E32,$D$6:$D$106,D32)) -> 0 | V32: 2 | W32: Basic | Y32: C | Z32: =IF(Q32="","",(Q32-T32)/Q32) -> 1 | AA32: =IF(Y32=$Z$2,IF(B32="","",AB32*B32),AB32) -> 0 | AB32: =IF(Y32="LO",P32*B32,P32) -> 0
A33: =A32 -> 0 | B33: {=_xlfn.IFS(Y33=$Z$2,IF(U33="","",IF(G33/F33=0,U33/Q33,G33/F33)),Y33=$Z$3,0,Y33=$Z$4,1)} -> 1 | C33: =IF(AND(D32=D33,OR(E33=E32,Y33=$Z$3)),C32,IF(E33="","",C32+1)) -> 1 | F33: =IF(E33=E32,F32,0) -> 0 | G33: =IF(O33="Continued","",F33) -> 0 | H33: =IF(O33="Continued","",F33) -> 0 | I33: {=_xlfn.IFS(Y33=$Z$4,F33,Y33=$Z$3,0,Y33=#REF!,0,Y33=$Z$2,F33-1)} -> 0 | J33: {=_xlfn.IFS(Y33=$Z$4,F33,Y33=$Z$3,0,Y33=#REF!,0,Y33=$Z$2,F33-1)} -> 0 | K33: 0 | Q33: =(IF(D33="Q",F33*$O$1,IF(D33="O",F33*$O$2,F33*$O$3))*IF(F33<$F$2,1,IF(F33<$F$3,0.9,0.875)))+$F$1 -> 0.16666667 | R33: 0 | T33: =R33+S33 -> 0 | U33: =IF(O33="Continued","",SUMIFS($T$6:$T$106,$E$6:$E$106,E33,$D$6:$D$106,D33)) -> 0 | V33: 2 | W33: Basic | Y33: C | Z33: =IF(Q33="","",(Q33-T33)/Q33) -> 1 | AA33: =IF(Y33=$Z$2,IF(B33="","",AB33*B33),AB33) -> 0 | AB33: =IF(Y33="LO",P33*B33,P33) -> 0
A34: =A33 -> 0 | B34: {=_xlfn.IFS(Y34=$Z$2,IF(U34="","",IF(G34/F34=0,U34/Q34,G34/F34)),Y34=$Z$3,0,Y34=$Z$4,1)} -> 1 | C34: =IF(AND(D33=D34,OR(E34=E33,Y34=$Z$3)),C33,IF(E34="","",C33+1)) -> 1 | F34: =IF(E34=E33,F33,0) -> 0 | G34: =IF(O34="Continued","",F34) -> 0 | H34: =IF(O34="Continued","",F34) -> 0 | I34: {=_xlfn.IFS(Y34=$Z$4,F34,Y34=$Z$3,0,Y34=#REF!,0,Y34=$Z$2,F34-1)} -> 0 | J34: {=_xlfn.IFS(Y34=$Z$4,F34,Y34=$Z$3,0,Y34=#REF!,0,Y34=$Z$2,F34-1)} -> 0 | K34: 0 | Q34: =(IF(D34="Q",F34*$O$1,IF(D34="O",F34*$O$2,F34*$O$3))*IF(F34<$F$2,1,IF(F34<$F$3,0.9,0.875)))+$F$1 -> 0.16666667 | R34: 0 | T34: =R34+S34 -> 0 | U34: =IF(O34="Continued","",SUMIFS($T$6:$T$106,$E$6:$E$106,E34,$D$6:$D$106,D34)) -> 0 | V34: 2 | W34: Basic | Y34: C | Z34: =IF(Q34="","",(Q34-T34)/Q34) -> 1 | AA34: =IF(Y34=$Z$2,IF(B34="","",AB34*B34),AB34) -> 0 | AB34: =IF(Y34="LO",P34*B34,P34) -> 0
A35: =A34 -> 0 | B35: {=_xlfn.IFS(Y35=$Z$2,IF(U35="","",IF(G35/F35=0,U35/Q35,G35/F35)),Y35=$Z$3,0,Y35=$Z$4,1)} -> 1 | C35: =IF(AND(D34=D35,OR(E35=E34,Y35=$Z$3)),C34,IF(E35="","",C34+1)) -> 1 | F35: =IF(E35=E34,F34,0) -> 0 | G35: =IF(O35="Continued","",F35) -> 0 | H35: =IF(O35="Continued","",F35) -> 0 | I35: {=_xlfn.IFS(Y35=$Z$4,F35,Y35=$Z$3,0,Y35=#REF!,0,Y35=$Z$2,F35-1)} -> 0 | J35: {=_xlfn.IFS(Y35=$Z$4,F35,Y35=$Z$3,0,Y35=#REF!,0,Y35=$Z$2,F35-1)} -> 0 | K35: 0 | Q35: =(IF(D35="Q",F35*$O$1,IF(D35="O",F35*$O$2,F35*$O$3))*IF(F35<$F$2,1,IF(F35<$F$3,0.9,0.875)))+$F$1 -> 0.16666667 | R35: 0 | T35: =R35+S35 -> 0 | U35: =IF(O35="Continued","",SUMIFS($T$6:$T$106,$E$6:$E$106,E35,$D$6:$D$106,D35)) -> 0 | V35: 2 | W35: Basic | Y35: C | Z35: =IF(Q35="","",(Q35-T35)/Q35) -> 1 | AA35: =IF(Y35=$Z$2,IF(B35="","",AB35*B35),AB35) -> 0 | AB35: =IF(Y35="LO",P35*B35,P35) -> 0
... A54: =A53 -> 0 | B54: {=_xlfn.IFS(Y54=$Z$2,IF(U54="","",IF(G54/F54=0,U54/Q54,G54/F54)),Y54=$Z$3,0,Y54=$Z$4,1)} -> 1 | C54: =IF(AND(D53=D54,OR(E54=E53,Y54=$Z$3)),C53,IF(E54="","",C53+1)) -> 1 | F54: =IF(E54=E53,F53,0) -> 0 | G54: =IF(O54="Continued","",F54) -> 0 | H54: =IF(O54="Continued","",F54) -> 0 | I54: {=_xlfn.IFS(Y54=$Z$4,F54,Y54=$Z$3,0,Y54=#REF!,0,Y54=$Z$2,F54-1)} -> 0 | J54: {=_xlfn.IFS(Y54=$Z$4,F54,Y54=$Z$3,0,Y54=#REF!,0,Y54=$Z$2,F54-1)} -> 0 | K54: 0 | Q54: =(IF(D54="Q",F54*$O$1,IF(D54="O",F54*$O$2,F54*$O$3))*IF(F54<$F$2,1,IF(F54<$F$3,0.9,0.875)))+$F$1 -> 0.16666667 | R54: 0 | T54: =R54+S54 -> 0 | U54: =IF(O54="Continued","",SUMIFS($T$6:$T$106,$E$6:$E$106,E54,$D$6:$D$106,D54)) -> 0 | V54: 2 | W54: Basic | Y54: C | Z54: =IF(Q54="","",(Q54-T54)/Q54) -> 1 | AA54: =IF(Y54=$Z$2,IF(B54="","",AB54*B54),AB54) -> 0 | AB54: =IF(Y54="LO",P54*B54,P54) -> 0
A55: =A54 -> 0 | B55: {=_xlfn.IFS(Y55=$Z$2,IF(U55="","",IF(G55/F55=0,U55/Q55,G55/F55)),Y55=$Z$3,0,Y55=$Z$4,1)} -> 1 | C55: =IF(AND(D54=D55,OR(E55=E54,Y55=$Z$3)),C54,IF(E55="","",C54+1)) -> 1 | F55: =IF(E55=E54,F54,0) -> 0 | G55: =IF(O55="Continued","",F55) -> 0 | H55: =IF(O55="Continued","",F55) -> 0 | I55: {=_xlfn.IFS(Y55=$Z$4,F55,Y55=$Z$3,0,Y55=#REF!,0,Y55=$Z$2,F55-1)} -> 0 | J55: {=_xlfn.IFS(Y55=$Z$4,F55,Y55=$Z$3,0,Y55=#REF!,0,Y55=$Z$2,F55-1)} -> 0 | K55: 0 | Q55: =(IF(D55="Q",F55*$O$1,IF(D55="O",F55*$O$2,F55*$O$3))*IF(F55<$F$2,1,IF(F55<$F$3,0.9,0.875)))+$F$1 -> 0.16666667 | R55: 0 | T55: =R55+S55 -> 0 | U55: =IF(O55="Continued","",SUMIFS($T$8:$T$108,$E$8:$E$108,E55,$D$8:$D$108,D55)) -> 0 | V55: 2 | W55: Basic | Y55: C | Z55: =IF(Q55="","",(Q55-T55)/Q55) -> 1 | AA55: =IF(Y55=$Z$2,IF(B55="","",AB55*B55),AB55) -> 0 | AB55: =IF(Y55="LO",P55*B55,P55) -> 0
A56: =A55 -> 0 | B56: {=_xlfn.IFS(Y56=$Z$2,IF(U56="","",IF(G56/F56=0,U56/Q56,G56/F56)),Y56=$Z$3,0,Y56=$Z$4,1)} -> 1 | C56: =IF(AND(D55=D56,OR(E56=E55,Y56=$Z$3)),C55,IF(E56="","",C55+1)) -> 1 | F56: =IF(E56=E55,F55,0) -> 0 | G56: =IF(O56="Continued","",F56) -> 0 | H56: =IF(O56="Continued","",F56) -> 0 | I56: {=_xlfn.IFS(Y56=$Z$4,F56,Y56=$Z$3,0,Y56=#REF!,0,Y56=$Z$2,F56-1)} -> 0 | J56: {=_xlfn.IFS(Y56=$Z$4,F56,Y56=$Z$3,0,Y56=#REF!,0,Y56=$Z$2,F56-1)} -> 0 | K56: 0 | Q56: =(IF(D56="Q",F56*$O$1,IF(D56="O",F56*$O$2,F56*$O$3))*IF(F56<$F$2,1,IF(F56<$F$3,0.9,0.875)))+$F$1 -> 0.16666667 | R56: 0 | T56: =R56+S56 -> 0 | U56: =IF(O56="Continued","",SUMIFS($T$8:$T$108,$E$8:$E$108,E56,$D$8:$D$108,D56)) -> 0 | V56: 2 | W56: Basic | Y56: C | Z56: =IF(Q56="","",(Q56-T56)/Q56) -> 1 | AA56: =IF(Y56=$Z$2,IF(B56="","",AB56*B56),AB56) -> 0 | AB56: =IF(Y56="LO",P56*B56,P56) -> 0
A57: =A56 -> 0 | B57: {=_xlfn.IFS(Y57=$Z$2,IF(U57="","",IF(G57/F57=0,U57/Q57,G57/F57)),Y57=$Z$3,0,Y57=$Z$4,1)} -> 1 | C57: =IF(AND(D56=D57,OR(E57=E56,Y57=$Z$3)),C56,IF(E57="","",C56+1)) -> 1 | F57: =IF(E57=E56,F56,0) -> 0 | G57: =IF(O57="Continued","",F57) -> 0 | H57: =IF(O57="Continued","",F57) -> 0 | I57: {=_xlfn.IFS(Y57=$Z$4,F57,Y57=$Z$3,0,Y57=#REF!,0,Y57=$Z$2,F57-1)} -> 0 | J57: {=_xlfn.IFS(Y57=$Z$4,F57,Y57=$Z$3,0,Y57=#REF!,0,Y57=$Z$2,F57-1)} -> 0 | K57: 0 | Q57: =(IF(D57="Q",F57*$O$1,IF(D57="O",F57*$O$2,F57*$O$3))*IF(F57<$F$2,1,IF(F57<$F$3,0.9,0.875)))+$F$1 -> 0.16666667 | R57: 0 | T57: =R57+S57 -> 0 | U57: =IF(O57="Continued","",SUMIFS($T$8:$T$108,$E$8:$E$108,E57,$D$8:$D$108,D57)) -> 0 | V57: 2 | W57: Basic | Y57: C | Z57: =IF(Q57="","",(Q57-T57)/Q57) -> 1 | AA57: =IF(Y57=$Z$2,IF(B57="","",AB57*B57),AB57) -> 0 | AB57: =IF(Y57="LO",P57*B57,P57) -> 0
A58: =A57 -> 0 | B58: {=_xlfn.IFS(Y58=$Z$2,IF(U58="","",IF(G58/F58=0,U58/Q58,G58/F58)),Y58=$Z$3,0,Y58=$Z$4,1)} -> 1 | C58: =IF(AND(D57=D58,OR(E58=E57,Y58=$Z$3)),C57,IF(E58="","",C57+1)) -> 1 | F58: =IF(E58=E57,F57,0) -> 0 | G58: =IF(O58="Continued","",F58) -> 0 | H58: =IF(O58="Continued","",F58) -> 0 | I58: {=_xlfn.IFS(Y58=$Z$4,F58,Y58=$Z$3,0,Y58=#REF!,0,Y58=$Z$2,F58-1)} -> 0 | J58: {=_xlfn.IFS(Y58=$Z$4,F58,Y58=$Z$3,0,Y58=#REF!,0,Y58=$Z$2,F58-1)} -> 0 | K58: 0 | Q58: =(IF(D58="Q",F58*$O$1,IF(D58="O",F58*$O$2,F58*$O$3))*IF(F58<$F$2,1,IF(F58<$F$3,0.9,0.875)))+$F$1 -> 0.16666667 | R58: 0 | T58: =R58+S58 -> 0 | U58: =IF(O58="Continued","",SUMIFS($T$8:$T$108,$E$8:$E$108,E58,$D$8:$D$108,D58)) -> 0 | V58: 2 | W58: Basic | Y58: C | Z58: =IF(Q58="","",(Q58-T58)/Q58) -> 1 | AA58: =IF(Y58=$Z$2,IF(B58="","",AB58*B58),AB58) -> 0 | AB58: =IF(Y58="LO",P58*B58,P58) -> 0
...

Sheet Sheet1
P1: Value Range | Q1: Order Frequency | R1: Quote Frequency
I2: Row Labels | J2: ∑ Value (NZD) | K2: Count of Q/O | L2: % of Total Value | M2: ∑ Time | N2: % of ∑ Time | O2: 500 | P2: ="$0-"&O2 -> $0-500 | Q2: {=FREQUENCY(Production_Center!K21:K49,Sheet1!$O$2:$O$9)} -> 29 | R2: {=FREQUENCY(Production_Center!K8:K20,Sheet1!$O$2:$O$9)} -> 13
I3: (blank) | J3: 0 | L3: #DIV/0! | M3: 0 | N3: #DIV/0! | O3: 2000 | P3: ="$"&O2+1&"-"&O3 -> $501-2000 | Q3: 0 | R3: 0
I4: (blank) | J4: 0 | L4: #DIV/0! | M4: 0 | N4: #DIV/0! | O4: 5000 | P4: ="$"&O3+1&"-"&O4 -> $2001-5000 | Q4: 0 | R4: 0
I5: Grand Total | J5: 0 | L5: #DIV/0! | M5: 0 | N5: #DIV/0! | O5: 10000 | P5: ="$"&O4+1&"-"&O5 -> $5001-10000 | Q5: 0 | R5: 0
O6: 15000 | P6: ="$"&O5+1&"-"&O6 -> $10001-15000 | Q6: 0 | R6: 0
O7: 25000 | P7: ="$"&O6+1&"-"&O7 -> $15001-25000 | Q7: 0 | R7: 0
O8: 50000 | P8: ="$"&O7+1&"-"&O8 -> $25001-50000 | Q8: 0 | R8: 0
O9: 75000 | P9: ="$"&O8+1&"-"&O9 -> $50001-75000 | Q9: 0 | R9: 0
P10: ="$"&O9+1&"+"&O10 -> $75001+ | Q10: 0 | R10: 0
O28: Ordering Customers | P28: ∑ Value (NZD) | Q28: Count of Orders | R28: % of ∑ Value
O34: Quoted Customers | P34: ∑ Value (NZD) | Q34: Count of Quotes | R34: % of ∑ Value
O41: Job Types | P41: ∑ Value (NZD) | Q41: Count of Q/O | R41: ∑ Time
O42: O | P42: 446917.58 | Q42: 29 | R42: 32.55
O43: Q | P43: 15334.83 | Q43: 13 | R43: 10.15

Sheet Summary_Charts
A1: Daily Worklog Summary — Production Center
A2: Source: Production_Center!D7:U49 (Type, Value NZ$, RM Time, Customer)
A4: 1) Quote vs Order | F4: 2) Top Customers by Value & Time | AB4: Top Orders (live)
A5: Type | B5: Jobs | C5: Value (NZ$) | D5: RM Time (hrs) | F5: Customer | G5: Value (NZ$) | H5: RM Time (hrs) | AB5: Customer | AC5: Value (NZ$) | AD5: Count | AE5: Value % | AF5: Customer | AG5: Count | AH5: Value (NZ$)
A6: Quote | B6: =COUNTIF(Production_Center!D8:D49,"Q") -> 0 | C6: =SUMIF(Production_Center!D8:D49,"Q",Production_Center!K8:K49) -> 0 | D6: =SUMIF(Production_Center!D8:D49,"Q",Production_Center!U8:U49) -> 0 | F6: {=_xlfn.LET(_xlpm.c,Production_Center!L8:L49,_xlpm.v,Production_Center!K8:K49,_xlpm.u,_xlfn.UNIQUE(_xlfn._xlws.FILTER(_xlpm.c,_xlpm.c<>"")),_xlpm.vs,_xlfn.MAP(_xlpm.u,_xlfn.LAMBDA(_xlpm.x,SUMIF(_xlpm.c,_xlpm.x,_xlpm.v))),_xlfn.TAKE(_xlfn.SORTBY(_xlpm.u,_xlpm.vs,-1),10))} -> #VALUE! | G6: {=_xlfn.LET(_xlpm.c,Production_Center!L8:L49,_xlpm.v,Production_Center!K8:K49,_xlpm.u,_xlfn.UNIQUE(_xlfn._xlws.FILTER(_xlpm.c,_xlpm.c<>"")),_xlpm.vs,_xlfn.MAP(_xlpm.u,_xlfn.LAMBDA(_xlpm.x,SUMIF(_xlpm.c,_xlpm.x,_xlpm.v))),_xlfn.TAKE(_xlfn.SORTBY(_xlpm.vs,_xlpm.vs,-1),10))} -> #VALUE! | H6: {=_xlfn.LET(_xlpm.c,Production_Center!L8:L49,_xlpm.v,Production_Center!K8:K49,_xlpm.t,Production_Center!U8:U49,_xlpm.u,_xlfn.UNIQUE(_xlfn._xlws.FILTER(_xlpm.c,_xlpm.c<>"")),_xlpm.vs,_xlfn.MAP(_xlpm.u,_xlfn.LAMBDA(_xlpm.x,SUMIF(_xlpm.c,_xlpm.x,_xlpm.v))),_xlpm.ts,_xlfn.MAP(_xlpm.u,_xlfn.LAMBDA(_xlpm.x,SUMIF(_xlpm.c,_xlpm.x,_xlpm.t))),_xlfn.TAKE(_xlfn.SORTBY(_xlpm.ts,_xlpm.vs,-1),10))} -> #VALUE! | AB6: {=_xlfn.LET(_xlpm.t,Production_Center!D8:D49,_xlpm.c,Production_Center!L8:L49,_xlpm.v,Production_Center!K8:K49,_xlpm.m,(_xlpm.t="O")*ISNUMBER(_xlpm.v)*(_xlpm.c<>""),_xlpm.uc,_xlfn.UNIQUE(_xlfn._xlws.FILTER(_xlpm.c,_xlpm.m=1)),_xlpm.tv,_xlfn.MAP(_xlpm.uc,_xlfn.LAMBDA(_xlpm.x,SUMIFS(_xlpm.v,_xlpm.c,_xlpm.x,_xlpm.t,"O"))),_xlpm.tc,_xlfn.MAP(_xlpm.uc,_xlfn.LAMBDA(_xlpm.x,COUNTIFS(_xlpm.c,_xlpm.x,_xlpm.t,"O"))),_xlpm.so,_xlfn.SORTBY(_xlfn.HSTACK(_xlpm.uc,_xlpm.tv,_xlpm.tc),_xlpm.tv,-1),_xlpm.top4n,INDEX(_xlfn.TAKE(_xlpm.so,4),,1),_xlpm.top4v,INDEX(_xlfn.TAKE(_xlpm.so,4),,2),_xlpm.top4c,INDEX(_xlfn.TAKE(_xlpm.so,4),,3),_xlpm.rest,_xlfn.DROP(_xlpm.so,4),_xlfn.HSTACK(_xlfn.VSTACK(_xlpm.top4n,"OTHER CUSTOMERS"),_xlfn.VSTACK(_xlpm.top4v,SUM(INDEX(_xlpm.rest,,2))),_xlfn.VSTACK(_xlpm.top4c,SUM(INDEX(_xlpm.rest,,3)))))} -> #VALUE! | AE6: =AC6/SUM($AC$6:$AC$10) -> #DIV/0! | AF6: =AB6 -> #VALUE! | AG6: =AD6 -> 0 | AH6: =AC6 -> 0
A7: Order | B7: =COUNTIF(Production_Center!D8:D49,"O") -> 0 | C7: =SUMIF(Production_Center!D8:D49,"O",Production_Center!K8:K49) -> 0 | D7: =SUMIF(Production_Center!D8:D49,"O",Production_Center!U8:U49) -> 0 | AE7: =AC7/SUM($AC$6:$AC$10) -> #DIV/0! | AF7: =AB7 -> 0 | AG7: =AD7 -> 0 | AH7: =AC7 -> 0
AE8: =AC8/SUM($AC$6:$AC$10) -> #DIV/0! | AF8: =AB8 -> 0 | AG8: =AD8 -> 0 | AH8: =AC8 -> 0
AE9: =AC9/SUM($AC$6:$AC$10) -> #DIV/0! | AF9: =AB9 -> 0 | AG9: =AD9 -> 0 | AH9: =AC9 -> 0
AE10: =AC10/SUM($AC$6:$AC$10) -> #DIV/0! | AF10: =AB10 -> 0 | AG10: =AD10 -> 0 | AH10: =AC10 -> 0
N20: Box-plot source
N21: Type | O21: RM Time (hrs) | P21: Value (NZ$) | Q21: Value Band | S21: Value Band | T21: RM Time (hrs) | U21: Type | V21: Value (NZ$) | W21: Order Value Band | X21: RM Time (hrs) | Y21: Quote Value Band | Z21: RM Time (hrs)
N22: {=_xlfn._xlws.FILTER(Production_Center!D8:D49,(Production_Center!U8:U49<>"")*(Production_Center!K8:K49<>"")*(Production_Center!K8:K49<>0))} -> #VALUE! | O22: {=_xlfn._xlws.FILTER(Production_Center!U8:U49,(Production_Center!U8:U49<>"")*(Production_Center!K8:K49<>"")*(Production_Center!K8:K49<>0))} -> #VALUE! | P22: {=_xlfn._xlws.FILTER(Production_Center!K8:K49,(Production_Center!U8:U49<>"")*(Production_Center!K8:K49<>"")*(Production_Center!K8:K49<>0))} -> #VALUE! | Q22: {=IF(P22:P57="","",_xlfn.IFS(P22:P57<=500,"$0-500",P22:P57<=2000,"$501-2K",P22:P57<=5000,"$2K-5K",P22:P57<=10000,"$5K-10K",P22:P57<=25000,"$10K-25K",TRUE,"$25K+"))} -> #VALUE! | S22: {=_xlfn.ANCHORARRAY(Q22)} -> #VALUE! | T22: {=_xlfn.ANCHORARRAY(O22)} -> #VALUE! | U22: {=_xlfn.ANCHORARRAY(N22)} -> #VALUE! | V22: {=_xlfn.ANCHORARRAY(P22)} -> #VALUE! | W22: {=IFERROR(_xlfn._xlws.FILTER(_xlfn.ANCHORARRAY(Q22),_xlfn.ANCHORARRAY(N22)="O"),"")} | X22: {=IFERROR(_xlfn._xlws.FILTER(_xlfn.ANCHORARRAY(O22),_xlfn.ANCHORARRAY(N22)="O"),"")} | Y22: {=IFERROR(_xlfn._xlws.FILTER(_xlfn.ANCHORARRAY(Q22),_xlfn.ANCHORARRAY(N22)="Q"),"")} | Z22: {=IFERROR(_xlfn._xlws.FILTER(_xlfn.ANCHORARRAY(O22),_xlfn.ANCHORARRAY(N22)="Q"),"")}
AB25: Top Quotes (live)
AB26: Customer | AC26: Value (NZ$) | AD26: Count | AE26: Value % | AF26: Customer | AG26: Count | AH26: Value (NZ$)
AB27: {=_xlfn.LET(_xlpm.t,Production_Center!D8:D49,_xlpm.c,Production_Center!L8:L49,_xlpm.v,Production_Center!K8:K49,_xlpm.m,(_xlpm.t="Q")*ISNUMBER(_xlpm.v)*(_xlpm.c<>""),_xlpm.uc,_xlfn.UNIQUE(_xlfn._xlws.FILTER(_xlpm.c,_xlpm.m=1)),_xlpm.tv,_xlfn.MAP(_xlpm.uc,_xlfn.LAMBDA(_xlpm.x,SUMIFS(_xlpm.v,_xlpm.c,_xlpm.x,_xlpm.t,"Q"))),_xlpm.tc,_xlfn.MAP(_xlpm.uc,_xlfn.LAMBDA(_xlpm.x,COUNTIFS(_xlpm.c,_xlpm.x,_xlpm.t,"Q"))),_xlpm.so,_xlfn.SORTBY(_xlfn.HSTACK(_xlpm.uc,_xlpm.tv,_xlpm.tc),_xlpm.tv,-1),_xlpm.top4n,INDEX(_xlfn.TAKE(_xlpm.so,4),,1),_xlpm.top4v,INDEX(_xlfn.TAKE(_xlpm.so,4),,2),_xlpm.top4c,INDEX(_xlfn.TAKE(_xlpm.so,4),,3),_xlpm.rest,_xlfn.DROP(_xlpm.so,4),_xlfn.HSTACK(_xlfn.VSTACK(_xlpm.top4n,"OTHER CUSTOMERS"),_xlfn.VSTACK(_xlpm.top4v,SUM(INDEX(_xlpm.rest,,2))),_xlfn.VSTACK(_xlpm.top4c,SUM(INDEX(_xlpm.rest,,3)))))} -> #VALUE! | AE27: =AC27/SUM($AC$27:$AC$31) -> #DIV/0! | AF27: =AB27 -> #VALUE! | AG27: =AD27 -> 0 | AH27: =AC27 -> 0
AE28: =AC28/SUM($AC$27:$AC$31) -> #DIV/0! | AF28: =AB28 -> 0 | AG28: =AD28 -> 0 | AH28: =AC28 -> 0
AE29: =AC29/SUM($AC$27:$AC$31) -> #DIV/0! | AF29: =AB29 -> 0 | AG29: =AD29 -> 0 | AH29: =AC29 -> 0
AE30: =AC30/SUM($AC$27:$AC$31) -> #DIV/0! | AF30: =AB30 -> 0 | AG30: =AD30 -> 0 | AH30: =AC30 -> 0
AE31: =AC31/SUM($AC$27:$AC$31) -> #DIV/0! | AF31: =AB31 -> 0 | AG31: =AD31 -> 0 | AH31: =AC31 -> 0
AB45: Top Customers by Order Count
AB46: Customer | AC46: Order Count | AD46: Label
AB47: {=_xlfn.LET(_xlpm.t,Production_Center!D8:D49,_xlpm.c,Production_Center!L8:L49,_xlpm.v,Production_Center!K8:K49,_xlpm.m,(_xlpm.t="O")*ISNUMBER(_xlpm.v)*(_xlpm.c<>""),_xlpm.uc,_xlfn.UNIQUE(_xlfn._xlws.FILTER(_xlpm.c,_xlpm.m=1)),_xlpm.tc,_xlfn.MAP(_xlpm.uc,_xlfn.LAMBDA(_xlpm.x,COUNTIFS(_xlpm.c,_xlpm.x,_xlpm.t,"O"))),_xlpm.so,_xlfn.SORTBY(_xlfn.HSTACK(_xlpm.uc,_xlpm.tc),_xlpm.tc,-1),_xlpm.top4n,INDEX(_xlfn.TAKE(_xlpm.so,4),,1),_xlpm.top4c,INDEX(_xlfn.TAKE(_xlpm.so,4),,2),_xlpm.rest,_xlfn.DROP(_xlpm.so,4),_xlfn.HSTACK(_xlfn.VSTACK(_xlpm.top4n,"OTHER CUSTOMERS"),_xlfn.VSTACK(_xlpm.top4c,SUM(INDEX(_xlpm.rest,,2)))))} -> #VALUE! | AD47: =AB47&" ("&AC47&" | "&TEXT(AC47/SUM($AC$47:$AC$51),"0.0%")&")" -> #VALUE!
AD48: =AB48&" ("&AC48&" | "&TEXT(AC48/SUM($AC$47:$AC$51),"0.0%")&")" -> #DIV/0!
AD49: =AB49&" ("&AC49&" | "&TEXT(AC49/SUM($AC$47:$AC$51),"0.0%")&")" -> #DIV/0!
AD50: =AB50&" ("&AC50&" | "&TEXT(AC50/SUM($AC$47:$AC$51),"0.0%")&")" -> #DIV/0!
AD51: =AB51&" ("&AC51&" | "&TEXT(AC51/SUM($AC$47:$AC$51),"0.0%")&")" -> #DIV/0!
AB55: Top Customers by Quote Count
AB56: Customer | AC56: Quote Count | AD56: Label
AB57: {=_xlfn.LET(_xlpm.t,Production_Center!D8:D49,_xlpm.c,Production_Center!L8:L49,_xlpm.v,Production_Center!K8:K49,_xlpm.m,(_xlpm.t="Q")*ISNUMBER(_xlpm.v)*(_xlpm.c<>""),_xlpm.uc,_xlfn.UNIQUE(_xlfn._xlws.FILTER(_xlpm.c,_xlpm.m=1)),_xlpm.tc,_xlfn.MAP(_xlpm.uc,_xlfn.LAMBDA(_xlpm.x,COUNTIFS(_xlpm.c,_xlpm.x,_xlpm.t,"Q"))),_xlpm.so,_xlfn.SORTBY(_xlfn.HSTACK(_xlpm.uc,_xlpm.tc),_xlpm.tc,-1),_xlpm.top4n,INDEX(_xlfn.TAKE(_xlpm.so,4),,1),_xlpm.top4c,INDEX(_xlfn.TAKE(_xlpm.so,4),,2),_xlpm.rest,_xlfn.DROP(_xlpm.so,4),_xlfn.HSTACK(_xlfn.VSTACK(_xlpm.top4n,"OTHER CUSTOMERS"),_xlfn.VSTACK(_xlpm.top4c,SUM(INDEX(_xlpm.rest,,2)))))} -> #VALUE! | AD57: =AB57&" ("&AC57&" | "&TEXT(AC57/SUM($AC$57:$AC$61),"0.0%")&")" -> #VALUE!
AD58: =AB58&" ("&AC58&" | "&TEXT(AC58/SUM($AC$57:$AC$61),"0.0%")&")" -> #DIV/0!
AD59: =AB59&" ("&AC59&" | "&TEXT(AC59/SUM($AC$57:$AC$61),"0.0%")&")" -> #DIV/0!
AD60: =AB60&" ("&AC60&" | "&TEXT(AC60/SUM($AC$57:$AC$61),"0.0%")&")" -> #DIV/0!
AD61: =AB61&" ("&AC61&" | "&TEXT(AC61/SUM($AC$57:$AC$61),"0.0%")&")" -> #DIV/0!
AB65: Top Customers by Order RM Time
AB66: Customer | AC66: RM Time (hrs)
AB67: {=_xlfn.LET(_xlpm.t,Production_Center!D8:D49,_xlpm.c,Production_Center!L8:L49,_xlpm.r,Production_Center!U8:U49,_xlpm.m,(_xlpm.t="O")*ISNUMBER(_xlpm.r)*(_xlpm.c<>""),_xlpm.uc,_xlfn.UNIQUE(_xlfn._xlws.FILTER(_xlpm.c,_xlpm.m=1)),_xlpm.tr,_xlfn.MAP(_xlpm.uc,_xlfn.LAMBDA(_xlpm.x,SUMIFS(_xlpm.r,_xlpm.c,_xlpm.x,_xlpm.t,"O"))),_xlpm.so,_xlfn.SORTBY(_xlfn.HSTACK(_xlpm.uc,_xlpm.tr),_xlpm.tr,-1),_xlpm.top4n,INDEX(_xlfn.TAKE(_xlpm.so,4),,1),_xlpm.top4r,INDEX(_xlfn.TAKE(_xlpm.so,4),,2),_xlpm.rest,_xlfn.DROP(_xlpm.so,4),_xlfn.HSTACK(_xlfn.VSTACK(_xlpm.top4n,"OTHER CUSTOMERS"),_xlfn.VSTACK(_xlpm.top4r,SUM(INDEX(_xlpm.rest,,2)))))} -> #VALUE!
AB75: Top Customers by Quote RM Time
AB76: Customer | AC76: RM Time (hrs)
AB77: {=_xlfn.LET(_xlpm.t,Production_Center!D8:D49,_xlpm.c,Production_Center!L8:L49,_xlpm.r,Production_Center!U8:U49,_xlpm.m,(_xlpm.t="Q")*ISNUMBER(_xlpm.r)*(_xlpm.c<>""),_xlpm.uc,_xlfn.UNIQUE(_xlfn._xlws.FILTER(_xlpm.c,_xlpm.m=1)),_xlpm.tr,_xlfn.MAP(_xlpm.uc,_xlfn.LAMBDA(_xlpm.x,SUMIFS(_xlpm.r,_xlpm.c,_xlpm.x,_xlpm.t,"Q"))),_xlpm.so,_xlfn.SORTBY(_xlfn.HSTACK(_xlpm.uc,_xlpm.tr),_xlpm.tr,-1),_xlpm.top4n,INDEX(_xlfn.TAKE(_xlpm.so,4),,1),_xlpm.top4r,INDEX(_xlfn.TAKE(_xlpm.so,4),,2),_xlpm.rest,_xlfn.DROP(_xlpm.so,4),_xlfn.HSTACK(_xlfn.VSTACK(_xlpm.top4n,"OTHER CUSTOMERS"),_xlfn.VSTACK(_xlpm.top4r,SUM(INDEX(_xlpm.rest,,2)))))} -> #VALUE!

Sheet Descriptive_Stats
A1: Descriptive Statistics — Production Center Daily Worklog
A2: Source: Production_Center D8:D49 (Type), K8:K49 (Value NZ$), L8:L49 (Customer), U8:U49 (RM Time)
A3: Note: Rows with blank/zero Value or blank RM Time are excluded (continued/in-progress jobs).
A5: Descriptive Statistics | H5: Filtered data (helper) | S5: RM Time — Normal Fit Build
A6: Statistic | B6: Value (NZ$) — All | C6: Value (NZ$) — Orders | D6: Value (NZ$) — Quotes | E6: RM Time — All | F6: RM Time — Orders | G6: RM Time — Quotes | H6: Type | I6: Value (NZ$) | J6: RM Time (hrs) | L6: Type | M6: Value (NZ$) | N6: RM Time (hrs) | P6: Type | Q6: RM Time (hrs) | S6: Mean | T6: =AVERAGE(_xlfn.ANCHORARRAY(J7)) -> #VALUE!
A7: Count | B7: =COUNT(_xlfn.ANCHORARRAY(I7)) -> 0 | C7: =COUNTIFS(_xlfn.ANCHORARRAY(H7),"O") -> 0 | D7: =COUNTIFS(_xlfn.ANCHORARRAY(H7),"Q") -> 0 | E7: =COUNT(_xlfn.ANCHORARRAY(J7)) -> 0 | F7: =COUNTIFS(_xlfn.ANCHORARRAY(H7),"O") -> 0 | G7: =COUNTIFS(_xlfn.ANCHORARRAY(H7),"Q") -> 0 | H7: {=_xlfn._xlws.FILTER(Production_Center!D8:D49,(Production_Center!U8:U49<>"")*(Production_Center!K8:K49<>"")*(Production_Center!K8:K49<>0))} -> #VALUE! | I7: {=_xlfn._xlws.FILTER(Production_Center!K8:K49,(Production_Center!U8:U49<>"")*(Production_Center!K8:K49<>"")*(Production_Center!K8:K49<>0))} -> #VALUE! | J7: {=_xlfn._xlws.FILTER(Production_Center!U8:U49,(Production_Center!U8:U49<>"")*(Production_Center!K8:K49<>"")*(Production_Center!K8:K49<>0))} -> #VALUE! | L7: {=_xlfn.ANCHORARRAY(H7)} -> #VALUE! | M7: {=_xlfn.ANCHORARRAY(I7)} -> #VALUE! | N7: {=_xlfn.ANCHORARRAY(J7)} -> #VALUE! | P7: {=_xlfn.ANCHORARRAY(H7)} -> #VALUE! | Q7: {=_xlfn.ANCHORARRAY(J7)} -> #VALUE! | S7: Std Dev | T7: =_xlfn.STDEV.S(_xlfn.ANCHORARRAY(J7)) -> #VALUE!
A8: Sum | B8: =SUM(_xlfn.ANCHORARRAY(I7)) -> #VALUE! | C8: =SUMIFS(_xlfn.ANCHORARRAY(I7),_xlfn.ANCHORARRAY(H7),"O") -> 0 | D8: =SUMIFS(_xlfn.ANCHORARRAY(I7),_xlfn.ANCHORARRAY(H7),"Q") -> 0 | E8: =SUM(_xlfn.ANCHORARRAY(J7)) -> #VALUE! | F8: =SUMIFS(_xlfn.ANCHORARRAY(J7),_xlfn.ANCHORARRAY(H7),"O") -> 0 | G8: =SUMIFS(_xlfn.ANCHORARRAY(J7),_xlfn.ANCHORARRAY(H7),"Q") -> 0 | S8: Min | T8: =MIN(_xlfn.ANCHORARRAY(J7)) -> #VALUE!
A9: Mean | B9: =AVERAGE(_xlfn.ANCHORARRAY(I7)) -> #VALUE! | C9: =AVERAGEIFS(_xlfn.ANCHORARRAY(I7),_xlfn.ANCHORARRAY(H7),"O") -> #DIV/0! | D9: =AVERAGEIFS(_xlfn.ANCHORARRAY(I7),_xlfn.ANCHORARRAY(H7),"Q") -> #DIV/0! | E9: =AVERAGE(_xlfn.ANCHORARRAY(J7)) -> #VALUE! | F9: =AVERAGEIFS(_xlfn.ANCHORARRAY(J7),_xlfn.ANCHORARRAY(H7),"O") -> #DIV/0! | G9: =AVERAGEIFS(_xlfn.ANCHORARRAY(J7),_xlfn.ANCHORARRAY(H7),"Q") -> #DIV/0! | S9: Max | T9: =MAX(_xlfn.ANCHORARRAY(J7)) -> #VALUE!
A10: Median | B10: =MEDIAN(_xlfn.ANCHORARRAY(I7)) -> #VALUE! | C10: {=MEDIAN(_xlfn._xlws.FILTER(_xlfn.ANCHORARRAY(I7),_xlfn.ANCHORARRAY(H7)="O"))} -> #VALUE! | D10: {=MEDIAN(_xlfn._xlws.FILTER(_xlfn.ANCHORARRAY(I7),_xlfn.ANCHORARRAY(H7)="Q"))} -> #VALUE! | E10: =MEDIAN(_xlfn.ANCHORARRAY(J7)) -> #VALUE! | F10: {=MEDIAN(_xlfn._xlws.FILTER(_xlfn.ANCHORARRAY(J7),_xlfn.ANCHORARRAY(H7)="O"))} -> #VALUE! | G10: {=MEDIAN(_xlfn._xlws.FILTER(_xlfn.ANCHORARRAY(J7),_xlfn.ANCHORARRAY(H7)="Q"))} -> #VALUE! | S10: N | T10: =COUNT(_xlfn.ANCHORARRAY(J7)) -> 0
A11: Min | B11: =MIN(_xlfn.ANCHORARRAY(I7)) -> #VALUE! | C11: =_xlfn.MINIFS(_xlfn.ANCHORARRAY(I7),_xlfn.ANCHORARRAY(H7),"O") -> 0 | D11: =_xlfn.MINIFS(_xlfn.ANCHORARRAY(I7),_xlfn.ANCHORARRAY(H7),"Q") -> 0 | E11: =MIN(_xlfn.ANCHORARRAY(J7)) -> #VALUE! | F11: =_xlfn.MINIFS(_xlfn.ANCHORARRAY(J7),_xlfn.ANCHORARRAY(H7),"O") -> 0 | G11: =_xlfn.MINIFS(_xlfn.ANCHORARRAY(J7),_xlfn.ANCHORARRAY(H7),"Q") -> 0 | S11: Bin width | T11: 1
A12: Max | B12: =MAX(_xlfn.ANCHORARRAY(I7)) -> #VALUE! | C12: =_xlfn.MAXIFS(_xlfn.ANCHORARRAY(I7),_xlfn.ANCHORARRAY(H7),"O") -> 0 | D12: =_xlfn.MAXIFS(_xlfn.ANCHORARRAY(I7),_xlfn.ANCHORARRAY(H7),"Q") -> 0 | E12: =MAX(_xlfn.ANCHORARRAY(J7)) -> #VALUE! | F12: =_xlfn.MAXIFS(_xlfn.ANCHORARRAY(J7),_xlfn.ANCHORARRAY(H7),"O") -> 0 | G12: =_xlfn.MAXIFS(_xlfn.ANCHORARRAY(J7),_xlfn.ANCHORARRAY(H7),"Q") -> 0 | S12: Bins | T12: =_xlfn.CEILING.MATH((T9-T8)/T11)+1 -> #VALUE!
A13: Range | B13: =B12-B11 -> #VALUE! | C13: =C12-C11 -> 0 | D13: =D12-D11 -> 0 | E13: =E12-E11 -> #VALUE! | F13: =F12-F11 -> 0 | G13: =G12-G11 -> 0
A14: Q1 (25%) | B14: =_xlfn.QUARTILE.INC(_xlfn.ANCHORARRAY(I7),1) -> #VALUE! | C14: {=_xlfn.QUARTILE.INC(_xlfn._xlws.FILTER(_xlfn.ANCHORARRAY(I7),_xlfn.ANCHORARRAY(H7)="O"),1)} -> #VALUE! | D14: {=_xlfn.QUARTILE.INC(_xlfn._xlws.FILTER(_xlfn.ANCHORARRAY(I7),_xlfn.ANCHORARRAY(H7)="Q"),1)} -> #VALUE! | E14: =_xlfn.QUARTILE.INC(_xlfn.ANCHORARRAY(J7),1) -> #VALUE! | F14: {=_xlfn.QUARTILE.INC(_xlfn._xlws.FILTER(_xlfn.ANCHORARRAY(J7),_xlfn.ANCHORARRAY(H7)="O"),1)} -> #VALUE! | G14: {=_xlfn.QUARTILE.INC(_xlfn._xlws.FILTER(_xlfn.ANCHORARRAY(J7),_xlfn.ANCHORARRAY(H7)="Q"),1)} -> #VALUE! | S14: Bin upper | T14: Bin label | U14: Frequency | V14: Normal Expected
A15: Q3 (75%) | B15: =_xlfn.QUARTILE.INC(_xlfn.ANCHORARRAY(I7),3) -> #VALUE! | C15: {=_xlfn.QUARTILE.INC(_xlfn._xlws.FILTER(_xlfn.ANCHORARRAY(I7),_xlfn.ANCHORARRAY(H7)="O"),3)} -> #VALUE! | D15: {=_xlfn.QUARTILE.INC(_xlfn._xlws.FILTER(_xlfn.ANCHORARRAY(I7),_xlfn.ANCHORARRAY(H7)="Q"),3)} -> #VALUE! | E15: =_xlfn.QUARTILE.INC(_xlfn.ANCHORARRAY(J7),3) -> #VALUE! | F15: {=_xlfn.QUARTILE.INC(_xlfn._xlws.FILTER(_xlfn.ANCHORARRAY(J7),_xlfn.ANCHORARRAY(H7)="O"),3)} -> #VALUE! | G15: {=_xlfn.QUARTILE.INC(_xlfn._xlws.FILTER(_xlfn.ANCHORARRAY(J7),_xlfn.ANCHORARRAY(H7)="Q"),3)} -> #VALUE! | S15: {=$T$11*_xlfn.SEQUENCE($T$12)} -> #VALUE! | T15: {="≤"&TEXT(_xlfn.ANCHORARRAY(S15),"0.0")} -> #VALUE! | U15: {=FREQUENCY(_xlfn.ANCHORARRAY(J7),_xlfn.ANCHORARRAY(S15)-0.0001)} -> #VALUE! | V15: {=(_xlfn.NORM.DIST(_xlfn.ANCHORARRAY(S15),$T$6,$T$7,TRUE)-_xlfn.NORM.DIST(_xlfn.ANCHORARRAY(S15)-$T$11,$T$6,$T$7,TRUE))*$T$10} -> #VALUE!
A16: IQR | B16: =B15-B14 -> #VALUE! | C16: =C15-C14 -> #VALUE! | D16: =D15-D14 -> #VALUE! | E16: =E15-E14 -> #VALUE! | F16: =F15-F14 -> #VALUE! | G16: =G15-G14 -> #VALUE!
A17: Std Dev | B17: =_xlfn.STDEV.S(_xlfn.ANCHORARRAY(I7)) -> #VALUE! | C17: {=_xlfn.STDEV.S(_xlfn._xlws.FILTER(_xlfn.ANCHORARRAY(I7),_xlfn.ANCHORARRAY(H7)="O"))} -> #VALUE! | D17: {=_xlfn.STDEV.S(_xlfn._xlws.FILTER(_xlfn.ANCHORARRAY(I7),_xlfn.ANCHORARRAY(H7)="Q"))} -> #VALUE! | E17: =_xlfn.STDEV.S(_xlfn.ANCHORARRAY(J7)) -> #VALUE! | F17: {=_xlfn.STDEV.S(_xlfn._xlws.FILTER(_xlfn.ANCHORARRAY(J7),_xlfn.ANCHORARRAY(H7)="O"))} -> #VALUE! | G17: {=_xlfn.STDEV.S(_xlfn._xlws.FILTER(_xlfn.ANCHORARRAY(J7),_xlfn.ANCHORARRAY(H7)="Q"))} -> #VALUE!
A18: Variance | B18: =_xlfn.VAR.S(_xlfn.ANCHORARRAY(I7)) -> #VALUE! | C18: {=_xlfn.VAR.S(_xlfn._xlws.FILTER(_xlfn.ANCHORARRAY(I7),_xlfn.ANCHORARRAY(H7)="O"))} -> #VALUE! | D18: {=_xlfn.VAR.S(_xlfn._xlws.FILTER(_xlfn.ANCHORARRAY(I7),_xlfn.ANCHORARRAY(H7)="Q"))} -> #VALUE! | E18: =_xlfn.VAR.S(_xlfn.ANCHORARRAY(J7)) -> #VALUE! | F18: {=_xlfn.VAR.S(_xlfn._xlws.FILTER(_xlfn.ANCHORARRAY(J7),_xlfn.ANCHORARRAY(H7)="O"))} -> #VALUE! | G18: {=_xlfn.VAR.S(_xlfn._xlws.FILTER(_xlfn.ANCHORARRAY(J7),_xlfn.ANCHORARRAY(H7)="Q"))} -> #VALUE!
A19: CV (StdDev/Mean) | B19: =B17/B9 -> #VALUE! | C19: =C17/C9 -> #VALUE! | D19: =D17/D9 -> #VALUE! | E19: =E17/E9 -> #VALUE! | F19: =F17/F9 -> #VALUE! | G19: =G17/G9 -> #VALUE!
A20: Skewness | B20: =SKEW(_xlfn.ANCHORARRAY(I7)) -> #VALUE! | C20: {=SKEW(_xlfn._xlws.FILTER(_xlfn.ANCHORARRAY(I7),_xlfn.ANCHORARRAY(H7)="O"))} -> #VALUE! | D20: {=SKEW(_xlfn._xlws.FILTER(_xlfn.ANCHORARRAY(I7),_xlfn.ANCHORARRAY(H7)="Q"))} -> #VALUE! | E20: =SKEW(_xlfn.ANCHORARRAY(J7)) -> #VALUE! | F20: {=SKEW(_xlfn._xlws.FILTER(_xlfn.ANCHORARRAY(J7),_xlfn.ANCHORARRAY(H7)="O"))} -> #VALUE! | G20: {=SKEW(_xlfn._xlws.FILTER(_xlfn.ANCHORARRAY(J7),_xlfn.ANCHORARRAY(H7)="Q"))} -> #VALUE!
A21: Kurtosis | B21: =KURT(_xlfn.ANCHORARRAY(I7)) -> #VALUE! | C21: {=KURT(_xlfn._xlws.FILTER(_xlfn.ANCHORARRAY(I7),_xlfn.ANCHORARRAY(H7)="O"))} -> #VALUE! | D21: {=KURT(_xlfn._xlws.FILTER(_xlfn.ANCHORARRAY(I7),_xlfn.ANCHORARRAY(H7)="Q"))} -> #VALUE! | E21: =KURT(_xlfn.ANCHORARRAY(J7)) -> #VALUE! | F21: {=KURT(_xlfn._xlws.FILTER(_xlfn.ANCHORARRAY(J7),_xlfn.ANCHORARRAY(H7)="O"))} -> #VALUE! | G21: {=KURT(_xlfn._xlws.FILTER(_xlfn.ANCHORARRAY(J7),_xlfn.ANCHORARRAY(H7)="Q"))} -> #VALUE!
A23: Distribution Charts
